Workbook
Name Week0: HistoricalRank!$E$400:$G$531
Name Week3: HistoricalRank!$I$1:$K$132
Name Week1: HistoricalRank!$A$1:$C$132
Name Week12: HistoricalRank!$E$267:$G$398
Name Week7: HistoricalRank!$E$134:$G$265
Name Week13: HistoricalRank!$I$267:$K$398
Name standings: Standings!$A$1:$R$131
Name Week11: HistoricalRank!$A$267:$C$398
Name Week10: HistoricalRank!$Q$134:$S$265
Name confcors: Calculations!$E$2:$G$12
Name Week15: HistoricalRank!$Q$267:$S$398
Name Week8: HistoricalRank!$I$134:$K$265
Name Week6: HistoricalRank!$A$134:$C$265
Name Week9: HistoricalRank!$M$134:$O$265
Name Week5: HistoricalRank!$Q$1:$S$132
Name Week14: HistoricalRank!$M$267:$O$398
Name Week16: HistoricalRank!$A$400:$C$531
Name Week2: HistoricalRank!$E$1:$G$132
Name Week4: HistoricalRank!$M$1:$O$132

Sheet CurrentRank
B1: Week | C1: FINAL | D1: 2020 | G1: Current CCG Matchups
B2: Name | C2: Points | D2: Rk | F2: CORS | G2: AAC | H2: CS | I2: CORS | J2: MAC | K2: CS
A3: =IFERROR(VLOOKUP(B3,Standings!$A$2:$R$132,6,FALSE),0) -> SEC | B3: Alabama | C3: 96.59 | D3: 1 | F3: =IFERROR(VLOOKUP(G3,CurrentRank!$B$2:$C$132,2,FALSE),0) -> 72.9 | G3: =ConfStandings!A3 -> Cincinnati | H3: =(F4-F3)/2 -> -17.76 | I3: =IFERROR(VLOOKUP(J3,CurrentRank!$B$2:$C$132,2,FALSE),0) -> 51.75 | J3: =ConfStandings!A93 -> Buffalo | K3: =(I4-I3)/2 -> 4.47
A4: =IFERROR(VLOOKUP(B4,Standings!$A$2:$R$132,6,FALSE),0) -> B1G | B4: Ohio State | C4: 87.05 | D4: 2 | F4: =IFERROR(VLOOKUP(G4,CurrentRank!$B$2:$C$132,2,FALSE),0) -> 37.38 | G4: =ConfStandings!A11 -> Tulsa | H4: =(F3-F4)/2 -> 17.76 | I4: =IFERROR(VLOOKUP(J4,CurrentRank!$B$2:$C$132,2,FALSE),0) -> 60.69 | J4: =ConfStandings!A101 -> Ball State | K4: =(I3-I4)/2 -> -4.47
A5: =IFERROR(VLOOKUP(B5,Standings!$A$2:$R$132,6,FALSE),0) -> SEC | B5: Texas A&M | C5: 85.31 | D5: 3
A6: =IFERROR(VLOOKUP(B6,Standings!$A$2:$R$132,6,FALSE),0) -> ACC | B6: Clemson | C6: 84.24 | D6: 4 | G6: ACC | J6: MWC
A7: =IFERROR(VLOOKUP(B7,Standings!$A$2:$R$132,6,FALSE),0) -> BIG12 | B7: Oklahoma | C7: 81.57 | D7: 5 | F7: =IFERROR(VLOOKUP(G7,CurrentRank!$B$2:$C$132,2,FALSE),0) -> 84.24 | G7: =ConfStandings!J19 -> Clemson | H7: =(F8-F7)/2 -> -2.725 | I7: =IFERROR(VLOOKUP(J7,CurrentRank!$B$2:$C$132,2,FALSE),0) -> 38.02 | J7: =ConfStandings!A109 -> Boise State | K7: =(I8-I7)/2 -> 6.5
A8: =IFERROR(VLOOKUP(B8,Standings!$A$2:$R$132,6,FALSE),0) -> SEC | B8: Georgia | C8: 79.21 | D8: 6 | F8: =IFERROR(VLOOKUP(G8,CurrentRank!$B$2:$C$132,2,FALSE),0) -> 78.79 | G8: =ConfStandings!J20 -> Notre Dame | H8: =(F7-F8)/2 -> 2.725 | I8: =IFERROR(VLOOKUP(J8,CurrentRank!$B$2:$C$132,2,FALSE),0) -> 51.02 | J8: =ConfStandings!A117 -> San Jose State | K8: =(I7-I8)/2 -> -6.5
A9: =IFERROR(VLOOKUP(B9,Standings!$A$2:$R$132,6,FALSE),0) -> ACC | B9: Notre Dame | C9: 78.79 | D9: 7
A10: =IFERROR(VLOOKUP(B10,Standings!$A$2:$R$132,6,FALSE),0) -> BIG12 | B10: Iowa State | C10: 73.64 | D10: 8 | G10: B1G | J10: PAC12
A11: =IFERROR(VLOOKUP(B11,Standings!$A$2:$R$132,6,FALSE),0) -> AAC | B11: Cincinnati | C11: 72.9 | D11: 9 | F11: =IFERROR(VLOOKUP(G11,CurrentRank!$B$2:$C$132,2,FALSE),0) -> 87.05 | G11: =ConfStandings!A37 -> Ohio State | H11: =(F12-F11)/2 -> -7.41 | I11: =IFERROR(VLOOKUP(J11,CurrentRank!$B$2:$C$132,2,FALSE),0) -> 40.47 | J11: =ConfStandings!A125 -> Washington | K11: =(I12-I11)/2 -> 11.005
A12: =IFERROR(VLOOKUP(B12,Standings!$A$2:$R$132,6,FALSE),0) -> SUN | B12: UL-Lafayette | C12: 72.87 | D12: 10 | F12: =IFERROR(VLOOKUP(G12,CurrentRank!$B$2:$C$132,2,FALSE),0) -> 72.23 | G12: =ConfStandings!A46 -> Northwestern | H12: =(F11-F12)/2 -> 7.41 | I12: =IFERROR(VLOOKUP(J12,CurrentRank!$B$2:$C$132,2,FALSE),0) -> 62.48 | J12: =ConfStandings!A133 -> Southern Cal | K12: =(I11-I12)/2 -> -11.005
A13: =IFERROR(VLOOKUP(B13,Standings!$A$2:$R$132,6,FALSE),0) -> B1G | B13: Northwestern | C13: 72.23 | D13: 11
A14: =IFERROR(VLOOKUP(B14,Standings!$A$2:$R$132,6,FALSE),0) -> B1G | B14: Iowa | C14: 71.81 | D14: 12 | G14: BIG12 | J14: SEC
A15: =IFERROR(VLOOKUP(B15,Standings!$A$2:$R$132,6,FALSE),0) -> SUN | B15: Coastal Carolina | C15: 69.98 | D15: 13 | F15: =IFERROR(VLOOKUP(G15,CurrentRank!$B$2:$C$132,2,FALSE),0) -> 73.64 | G15: =ConfStandings!A55 -> Iowa State | H15: =(F16-F15)/2 -> 3.965 | I15: =IFERROR(VLOOKUP(J15,CurrentRank!$B$2:$C$132,2,FALSE),0) -> 79.21 | J15: =ConfStandings!A141 -> Georgia | K15: =(I16-I15)/2 -> 8.69
A16: =IFERROR(VLOOKUP(B16,Standings!$A$2:$R$132,6,FALSE),0) -> B1G | B16: Indiana | C16: 69.98 | D16: 13 | F16: =IFERROR(VLOOKUP(G16,CurrentRank!$B$2:$C$132,2,FALSE),0) -> 81.57 | G16: =ConfStandings!A56 -> Oklahoma | H16: =(F15-F16)/2 -> -3.965 | I16: =IFERROR(VLOOKUP(J16,CurrentRank!$B$2:$C$132,2,FALSE),0) -> 96.59 | J16: =ConfStandings!A150 -> Alabama | K16: =(I15-I16)/2 -> -8.69
A17: =IFERROR(VLOOKUP(B17,Standings!$A$2:$R$132,6,FALSE),0) -> IND | B17: BYU | C17: 69.33 | D17: 15
A18: =IFERROR(VLOOKUP(B18,Standings!$A$2:$R$132,6,FALSE),0) -> SEC | B18: Florida | C18: 68.03 | D18: 16 | G18: CUSA | J18: SUN
A19: =IFERROR(VLOOKUP(B19,Standings!$A$2:$R$132,6,FALSE),0) -> IND | B19: Liberty | C19: 65.58 | D19: 17 | F19: =IFERROR(VLOOKUP(G19,CurrentRank!$B$2:$C$132,2,FALSE),0) -> 33.45 | G19: =ConfStandings!A67 -> Marshall | H19: =(F20-F19)/2 -> -0.745 | I19: =IFERROR(VLOOKUP(J19,CurrentRank!$B$2:$C$132,2,FALSE),0) -> 69.98 | J19: =ConfStandings!A159 -> Coastal Carolina | K19: =(I20-I19)/2 -> 1.445
A20: =IFERROR(VLOOKUP(B20,Standings!$A$2:$R$132,6,FALSE),0) -> ACC | B20: North Carolina | C20: 63.1 | D20: 18 | F20: =IFERROR(VLOOKUP(G20,CurrentRank!$B$2:$C$132,2,FALSE),0) -> 31.96 | G20: =ConfStandings!A76 -> UAB | H20: =(F19-F20)/2 -> 0.745 | I20: =IFERROR(VLOOKUP(J20,CurrentRank!$B$2:$C$132,2,FALSE),0) -> 72.87 | J20: =ConfStandings!A166 -> UL-Lafayette | K20: =(I19-I20)/2 -> -1.445
A21: =IFERROR(VLOOKUP(B21,Standings!$A$2:$R$132,6,FALSE),0) -> PAC12 | B21: Southern Cal | C21: 62.48 | D21: 19
A22: =IFERROR(VLOOKUP(B22,Standings!$A$2:$R$132,6,FALSE),0) -> BIG12 | B22: Texas | C22: 62.29 | D22: 20 | G22: Current CORS W/L
A23: =IFERROR(VLOOKUP(B23,Standings!$A$2:$R$132,6,FALSE),0) -> MAC | B23: Ball State | C23: 60.69 | D23: 21 | G23: =CONCATENATE(M23, "-", O23) -> 394-164 | H23: =M23/(M23+O23) -> 0.70609319 | J23: Straight Up | L23: W | M23: =COUNTIF(WLSpread!AG2:AG1004, 1) -> 394 | N23: L | O23: =COUNTIF(WLSpread!AG2:AG1004, 0) -> 164
A24: =IFERROR(VLOOKUP(B24,Standings!$A$2:$R$132,6,FALSE),0) -> BIG12 | B24: Oklahoma State | C24: 59.34 | D24: 22
A25: =IFERROR(VLOOKUP(B25,Standings!$A$2:$R$132,6,FALSE),0) -> ACC | B25: Miami | C25: 57.15 | D25: 23 | G25: CORS Conference Ratings - CORS AVG
A26: =IFERROR(VLOOKUP(B26,Standings!$A$2:$R$132,6,FALSE),0) -> MAC | B26: Buffalo | C26: 51.75 | D26: 24 | G26: Conference | H26: CORS AVG | I26: RankAVG
A27: =IFERROR(VLOOKUP(B27,Standings!$A$2:$R$132,6,FALSE),0) -> MWC | B27: San Jose State | C27: 51.02 | D27: 25 | G27: =IFERROR(__xludf.DUMMYFUNCTION("QUERY(confcors,""SELECT E, F, G ORDER by F DESC"",0)"),"SEC") -> SEC | H27: =IFERROR(__xludf.DUMMYFUNCTION("""COMPUTED_VALUE"""),48.48285714285714) -> 48.482857 | I27: =IFERROR(__xludf.DUMMYFUNCTION("""COMPUTED_VALUE"""),48.5) -> 48.5
A28: =IFERROR(VLOOKUP(B28,Standings!$A$2:$R$132,6,FALSE),0) -> PAC12 | B28: Arizona State | C28: 44.06 | D28: 26 | G28: =IFERROR(__xludf.DUMMYFUNCTION("""COMPUTED_VALUE"""),"BIG12") -> BIG12 | H28: =IFERROR(__xludf.DUMMYFUNCTION("""COMPUTED_VALUE"""),47.63199999999999) -> 47.632 | I28: =IFERROR(__xludf.DUMMYFUNCTION("""COMPUTED_VALUE"""),50.9) -> 50.9
A29: =IFERROR(VLOOKUP(B29,Standings!$A$2:$R$132,6,FALSE),0) -> PAC12 | B29: Utah | C29: 43.66 | D29: 27 | G29: =IFERROR(__xludf.DUMMYFUNCTION("""COMPUTED_VALUE"""),"B1G") -> B1G | H29: =IFERROR(__xludf.DUMMYFUNCTION("""COMPUTED_VALUE"""),45.93142857142857) -> 45.931429 | I29: =IFERROR(__xludf.DUMMYFUNCTION("""COMPUTED_VALUE"""),57.0) -> 57
A30: =IFERROR(VLOOKUP(B30,Standings!$A$2:$R$132,6,FALSE),0) -> PAC12 | B30: Stanford | C30: 42.24 | D30: 28 | G30: =IFERROR(__xludf.DUMMYFUNCTION("""COMPUTED_VALUE"""),"IND") -> IND | H30: =IFERROR(__xludf.DUMMYFUNCTION("""COMPUTED_VALUE"""),45.653999999999996) -> 45.654 | I30: =IFERROR(__xludf.DUMMYFUNCTION("""COMPUTED_VALUE"""),67.0) -> 67
A31: =IFERROR(VLOOKUP(B31,Standings!$A$2:$R$132,6,FALSE),0) -> BIG12 | B31: TCU | C31: 41.9 | D31: 29 | G31: =IFERROR(__xludf.DUMMYFUNCTION("""COMPUTED_VALUE"""),"ACC") -> ACC | H31: =IFERROR(__xludf.DUMMYFUNCTION("""COMPUTED_VALUE"""),43.836) -> 43.836 | I31: =IFERROR(__xludf.DUMMYFUNCTION("""COMPUTED_VALUE"""),56.2) -> 56.2
A32: =IFERROR(VLOOKUP(B32,Standings!$A$2:$R$132,6,FALSE),0) -> AAC | B32: Central Florida | C32: 41.86 | D32: 30 | G32: =IFERROR(__xludf.DUMMYFUNCTION("""COMPUTED_VALUE"""),"PAC12") -> PAC12 | H32: =IFERROR(__xludf.DUMMYFUNCTION("""COMPUTED_VALUE"""),39.979166666666664) -> 39.979167 | I32: =IFERROR(__xludf.DUMMYFUNCTION("""COMPUTED_VALUE"""),48.0) -> 48
A33: =IFERROR(VLOOKUP(B33,Standings!$A$2:$R$132,6,FALSE),0) -> PAC12 | B33: UCLA | C33: 41.14 | D33: 31 | G33: =IFERROR(__xludf.DUMMYFUNCTION("""COMPUTED_VALUE"""),"SUN") -> SUN | H33: =IFERROR(__xludf.DUMMYFUNCTION("""COMPUTED_VALUE"""),39.688) -> 39.688 | I33: =IFERROR(__xludf.DUMMYFUNCTION("""COMPUTED_VALUE"""),75.7) -> 75.7
A34: =IFERROR(VLOOKUP(B34,Standings!$A$2:$R$132,6,FALSE),0) -> B1G | B34: Wisconsin | C34: 41.11 | D34: 32 | G34: =IFERROR(__xludf.DUMMYFUNCTION("""COMPUTED_VALUE"""),"MAC") -> MAC | H34: =IFERROR(__xludf.DUMMYFUNCTION("""COMPUTED_VALUE"""),37.385) -> 37.385 | I34: =IFERROR(__xludf.DUMMYFUNCTION("""COMPUTED_VALUE"""),68.5) -> 68.5
A35: =IFERROR(VLOOKUP(B35,Standings!$A$2:$R$132,6,FALSE),0) -> PAC12 | B35: Washington | C35: 40.47 | D35: 33 | G35: =IFERROR(__xludf.DUMMYFUNCTION("""COMPUTED_VALUE"""),"MWC") -> MWC | H35: =IFERROR(__xludf.DUMMYFUNCTION("""COMPUTED_VALUE"""),35.63250000000001) -> 35.6325 | I35: =IFERROR(__xludf.DUMMYFUNCTION("""COMPUTED_VALUE"""),68.16666666666667) -> 68.166667
A36: =IFERROR(VLOOKUP(B36,Standings!$A$2:$R$132,6,FALSE),0) -> B1G | B36: Penn State | C36: 40.05 | D36: 34 | G36: =IFERROR(__xludf.DUMMYFUNCTION("""COMPUTED_VALUE"""),"AAC") -> AAC | H36: =IFERROR(__xludf.DUMMYFUNCTION("""COMPUTED_VALUE"""),35.51416666666667) -> 35.514167 | I36: =IFERROR(__xludf.DUMMYFUNCTION("""COMPUTED_VALUE"""),76.5) -> 76.5
A37: =IFERROR(VLOOKUP(B37,Standings!$A$2:$R$132,6,FALSE),0) -> SEC | B37: Mississippi | C37: 39.96 | D37: 35 | G37: =IFERROR(__xludf.DUMMYFUNCTION("""COMPUTED_VALUE"""),"CUSA") -> CUSA | H37: =IFERROR(__xludf.DUMMYFUNCTION("""COMPUTED_VALUE"""),28.65571428571428) -> 28.655714 | I37: =IFERROR(__xludf.DUMMYFUNCTION("""COMPUTED_VALUE"""),103.85714285714286) -> 103.85714
A38: =IFERROR(VLOOKUP(B38,Standings!$A$2:$R$132,6,FALSE),0) -> SEC | B38: Auburn | C38: 39.11 | D38: 36
A39: =IFERROR(VLOOKUP(B39,Standings!$A$2:$R$132,6,FALSE),0) -> BIG12 | B39: West Virginia | C39: 38.08 | D39: 37 | G39: CORS Conference Ratings - RANK AVG
A40: =IFERROR(VLOOKUP(B40,Standings!$A$2:$R$132,6,FALSE),0) -> MWC | B40: Boise State | C40: 38.02 | D40: 38 | G40: Conference | H40: CORS AVG | I40: RankAVG
...

Sheet HistoricalRank
A1: Week | B1: 1 | C1: 2020 | E1: Week | F1: 2 | G1: 2020 | I1: Week | J1: 3 | K1: 2020 | M1: Week | N1: 4 | O1: 2020 | Q1: Week | R1: 5 | S1: 2020
A2: Name | B2: Points | C2: Rk | E2: Name | F2: Points | G2: Rk | I2: Name | J2: Points | K2: Rk | M2: Name | N2: Points | O2: Rk | Q2: Name | R2: Points | S2: Rk
A3: Clemson | B3: 45.8 | C3: 1 | E3: Clemson | F3: 85.78 | G3: 1 | I3: Clemson | J3: 91.33 | K3: 1 | M3: Clemson | N3: 88.54 | O3: 1 | Q3: Alabama | R3: 91.15 | S3: 1
A4: Ohio State | B4: 45.32 | C4: 2 | E4: Notre Dame | F4: 75.57 | G4: 2 | I4: Notre Dame | J4: 81.45 | K4: 2 | M4: Alabama | N4: 83.91 | O4: 2 | Q4: Georgia | R4: 90.69 | S4: 2
A5: Alabama | B5: 44.18 | C5: 3 | E5: North Carolina | F5: 73.99 | G5: 3 | I5: Miami | J5: 80.21 | K5: 3 | M5: Miami | N5: 83.87 | O5: 3 | Q5: Clemson | R5: 89.43 | S5: 3
A6: Georgia | B6: 41.94 | C6: 4 | E6: Texas | F6: 68.26 | G6: 4 | I6: Central Florida | J6: 78.85 | K6: 4 | M6: Georgia | N6: 82.44 | O6: 4 | Q6: Florida | R6: 85.72 | S6: 4
A7: Oklahoma | B7: 41.52 | C7: 5 | E7: Oklahoma | F7: 67.55 | G7: 5 | I7: North Carolina | J7: 76.93 | K7: 5 | M7: Florida | N7: 80.89 | O7: 5 | Q7: Miami | R7: 85.49 | S7: 5
A8: LSU | B8: 41.03 | C8: 6 | E8: Alabama | F8: 65.08 | G8: 6 | I8: Texas | J8: 72.16 | K8: 6 | M8: Notre Dame | N8: 80.79 | O8: 6 | Q8: Oklahoma State | R8: 80.53 | S8: 6
A9: Penn State | B9: 39.65 | C9: 7 | E9: UL-Lafayette | F9: 64.7 | G9: 7 | I9: Oklahoma | J9: 71.06 | K9: 7 | M9: Texas | N9: 78.34 | O9: 7 | Q9: Notre Dame | R9: 80.23 | S9: 7
A10: Florida | B10: 39.2 | C10: 8 | E10: Memphis | F10: 64.52 | G10: 8 | I10: Alabama | J10: 68.86 | K10: 8 | M10: Central Florida | N10: 77.93 | O10: 8 | Q10: North Carolina | R10: 79.29 | S10: 8
A11: Oregon | B11: 38.94 | C11: 9 | E11: Georgia | F11: 63.47 | G11: 9 | I11: UL-Lafayette | J11: 67.68 | K11: 9 | M11: Auburn | N11: 77.21 | O11: 9 | Q11: Tennessee | R11: 73.45 | S11: 9
A12: Notre Dame | B12: 36.88 | C12: 10 | E12: LSU | F12: 61.75 | G12: 10 | I12: Georgia | J12: 66.76 | K12: 10 | M12: North Carolina | N12: 75.92 | O12: 10 | Q12: Cincinnati | R12: 71.88 | S12: 10
A13: Auburn | B13: 34.95 | C13: 11 | E13: Florida | F13: 61.6 | G13: 11 | I13: Memphis | J13: 66.39 | K13: 11 | M13: Cincinnati | N13: 69.04 | O13: 11 | Q13: BYU | R13: 71.53 | S13: 11
A14: Wisconsin | B14: 34.65 | C14: 12 | E14: Miami | F14: 58.98 | G14: 12 | I14: BYU | J14: 66.13 | K14: 12 | M14: Oklahoma State | N14: 67.72 | O14: 12 | Q14: UL-Lafayette | R14: 70.26 | S14: 12
... A134: Week | B134: 6 | C134: 2020 | E134: Week | F134: 7 | G134: 2020 | I134: Week | J134: 8 | K134: 2020 | M134: Week | N134: 9 | O134: 2020 | Q134: Week | R134: 10 | S134: 2020
A135: Name | B135: Points | C135: Rk | E135: Name | F135: Points | G135: Rk | I135: Name | J135: Points | K135: Rk | M135: Name | N135: Points | O135: Rk | Q135: Name | R135: Points | S135: Rk
A136: Clemson | B136: 93.16 | C136: 1 | E136: Clemson | F136: 95.81 | G136: 1 | I136: Clemson | J136: 94.65 | K136: 1 | M136: Clemson | N136: 94.26 | O136: 1 | Q136: Alabama | R136: 93.82 | S136: 1
A137: Alabama | B137: 92.3 | C137: 2 | E137: Alabama | F137: 93.43 | G137: 2 | I137: Alabama | J137: 92.87 | K137: 2 | M137: Alabama | N137: 93.88 | O137: 2 | Q137: Notre Dame | R137: 89.06 | S137: 2
A138: Georgia | B138: 92.11 | C138: 3 | E138: Oklahoma State | F138: 84.95 | G138: 3 | I138: Notre Dame | J138: 86.13 | K138: 3 | M138: Notre Dame | N138: 86.91 | O138: 3 | Q138: Ohio State | R138: 87.41 | S138: 3
A139: North Carolina | B139: 84.52 | C139: 4 | E139: Notre Dame | F139: 83.7 | G139: 4 | I139: Ohio State | J139: 83.94 | K139: 4 | M139: Ohio State | N139: 86.13 | O139: 4 | Q139: Clemson | R139: 83.7 | S139: 4
A140: Oklahoma State | B140: 83.55 | C140: 5 | E140: Georgia | F140: 82.53 | G140: 5 | I140: Oklahoma State | J140: 83.92 | K140: 5 | M140: Georgia | N140: 83.04 | O140: 5 | Q140: Cincinnati | R140: 80.98 | S140: 5
A141: Notre Dame | B141: 83.02 | C141: 6 | E141: BYU | F141: 77.19 | G141: 6 | I141: Georgia | J141: 81.26 | K141: 6 | M141: Cincinnati | N141: 80.87 | O141: 6 | Q141: Texas A&M | R141: 80.61 | S141: 6
A142: BYU | B142: 73.86 | C142: 7 | E142: Texas A&M | F142: 75.32 | G142: 7 | I142: Cincinnati | J142: 78.48 | K142: 7 | M142: Wisconsin | N142: 78.92 | O142: 7 | Q142: BYU | R142: 79.34 | S142: 7
A143: Cincinnati | B143: 73.07 | C143: 8 | E143: Cincinnati | F143: 74.26 | G143: 8 | I143: Wisconsin | J143: 76.88 | K143: 8 | M143: BYU | N143: 77.89 | O143: 8 | Q143: Florida | R143: 79.04 | S143: 8
A144: UL-Lafayette | B144: 72.23 | C144: 9 | E144: Miami | F144: 74.07 | G144: 9 | I144: BYU | J144: 76.58 | K144: 9 | M144: Texas A&M | N144: 77.48 | O144: 9 | Q144: Indiana | R144: 76.68 | S144: 9
A145: Florida | B145: 70.7 | C145: 10 | E145: Florida | F145: 72.77 | G145: 10 | I145: Texas A&M | J145: 74.99 | K145: 10 | M145: Florida | N145: 75.4 | O145: 10 | Q145: Wisconsin | R145: 75.78 | S145: 10
A146: Miami | B146: 70.01 | C146: 11 | E146: Southern Methodist | F146: 71.45 | G146: 11 | I146: Michigan | J146: 73.56 | K146: 11 | M146: Miami | N146: 74.23 | O146: 11 | Q146: Miami | R146: 75.25 | S146: 11
A147: Texas A&M | B147: 68.39 | C147: 12 | E147: Coastal Carolina | F147: 68.02 | G147: 12 | I147: Miami | J147: 73.25 | K147: 12 | M147: Coastal Carolina | N147: 73.88 | O147: 12 | Q147: Coastal Carolina | R147: 74.54 | S147: 12
... A267: Week | B267: 11 | C267: 2020 | E267: Week | F267: 12 | G267: 2020 | I267: Week | J267: 13 | K267: 2020 | M267: Week | N267: 14 | O267: 2020 | Q267: Week | R267: 15 | S267: 2020
A268: Name | B268: Points | C268: Rk | E268: Name | F268: Points | G268: Rk | I268: Name | J268: Points | K268: Rk | M268: Name | N268: Points | O268: Rk | Q268: Name | R268: Points | S268: Rk
A269: Alabama | B269: 93.72 | C269: 1 | E269: Alabama | F269: 94.37 | G269: 1 | I269: Alabama | J269: 95.16 | K269: 1 | M269: Alabama | N269: 95.75 | O269: 1 | Q269: Alabama | R269: 96.09 | S269: 1
A270: Notre Dame | B270: 89.8 | C270: 2 | E270: Notre Dame | F270: 89.43 | G270: 2 | I270: Notre Dame | J270: 90.44 | K270: 2 | M270: Notre Dame | N270: 90.95 | O270: 2 | Q270: Notre Dame | R270: 90.63 | S270: 2
A271: Ohio State | B271: 87.06 | C271: 3 | E271: Ohio State | F271: 87.18 | G271: 3 | I271: Ohio State | J271: 87.09 | K271: 3 | M271: Ohio State | N271: 88.77 | O271: 3 | Q271: Ohio State | R271: 88.48 | S271: 3
A272: Clemson | B272: 83.64 | C272: 4 | E272: Clemson | F272: 83.65 | G272: 4 | I272: Clemson | J272: 85.28 | K272: 4 | M272: Clemson | N272: 86.81 | O272: 4 | Q272: Clemson | R272: 86.71 | S272: 4
A273: Texas A&M | B273: 80.43 | C273: 5 | E273: Florida | F273: 80.67 | G273: 5 | I273: Florida | J273: 81.53 | K273: 5 | M273: Florida | N273: 83.15 | O273: 5 | Q273: Coastal Carolina | R273: 82.38 | S273: 5
A274: Wisconsin | B274: 80.06 | C274: 6 | E274: Texas A&M | F274: 80.19 | G274: 6 | I274: Texas A&M | J274: 81.12 | K274: 6 | M274: Texas A&M | N274: 82.37 | O274: 6 | Q274: Texas A&M | R274: 82.37 | S274: 6
A275: Florida | B275: 80 | C275: 7 | E275: Cincinnati | F275: 80.16 | G275: 7 | I275: Cincinnati | J275: 80.39 | K275: 7 | M275: Coastal Carolina | N275: 81.29 | O275: 7 | Q275: Cincinnati | R275: 80.82 | S275: 7
A276: Cincinnati | B276: 79.64 | C276: 8 | E276: BYU | F276: 79.39 | G276: 8 | I276: BYU | J276: 79.2 | K276: 8 | M276: Cincinnati | N276: 80.36 | O276: 8 | Q276: Indiana | R276: 79.06 | S276: 8
A277: BYU | B277: 79.2 | C277: 9 | E277: Northwestern | F277: 77.76 | G277: 9 | I277: Coastal Carolina | J277: 77.29 | K277: 9 | M277: Miami | N277: 79.1 | O277: 9 | Q277: Iowa State | R277: 78.13 | S277: 9
A278: Indiana | B278: 78.4 | C278: 10 | E278: Oregon | F278: 77.16 | G278: 10 | I278: Miami | J278: 75.99 | K278: 10 | M278: Indiana | N278: 78.18 | O278: 10 | Q278: Georgia | R278: 75.51 | S278: 10
...

Sheet WLSpread
A1: Week | B1: Away | C1: Home | D1: Away CORS | E1: ACORS Now | F1: Away Rank | G1: AR Now | H1: Home CORS | I1: HCORS Now | J1: Home Rank | K1: HR Now | L1: HFA Then | M1: HFA Now | N1: Rank Value | O1: GS | P1: RS | Q1: BEV | S1: AEV | U1: Neutral | V1: Matchup | W1: Underdog | X1: Favorite | Y1: Conf | Z1: Winner | AA1: Score | AB1: Loser | AC1: Score | AD1: OT | AE1: SD | AF1: Notes | AG1: W/L SU | AH1: W/L ATS | AJ1: Abilene Christian
A2: 2 | B2: Clemson | C2: Wake Forest | D2: =IFERROR(VLOOKUP(B2,Week1,2,FALSE),0) -> 45.8 | E2: =IF(ISBLANK(B2),,IFERROR(VLOOKUP(B2,CurrentRank!$B$2:$C$132,2,FALSE),0)) -> 84.24 | F2: =IFERROR(VLOOKUP(B2,Week1,3,FALSE),130) -> 1 | G2: =IF(ISBLANK(B2),,IFERROR(VLOOKUP(B2,CurrentRank!$B$2:$D$132,3,FALSE),130)) -> 4 | H2: =IFERROR(VLOOKUP(C2,Week1,2,FALSE),0) -> 6.67 | I2: =IF(ISBLANK(B2),,IFERROR(VLOOKUP(C2,CurrentRank!$B$2:$C$132,2,FALSE),0)) -> 36.48 | J2: =IFERROR(VLOOKUP(C2,Week1,3,FALSE),130) -> 35 | K2: =IF(ISBLANK(C2),,IFERROR(VLOOKUP(C2,CurrentRank!$B$2:$D$132,3,FALSE),130)) -> 52 | L2: =IF(U2= "Yes", 0, IF(ISBLANK(C2),,(D2+H2)*0.015)) -> 0.78705 | M2: =IF(U2= "Yes", 0, IF(ISBLANK(D2),,(E2+I2)*0.015)) -> 1.8108 | N2: =IF(ISBLANK(C2),,(F2+J2)/2) -> 18 | O2: =IF(H2=0,,(D2-(H2+L2))/2) -> 19.171475 | P2: =IF(ISBLANK(C2),,(E2-(I2+L2))/2) -> 23.486475 | Q2: =IF(ISBLANK(O2),,1-((ABS(O2/2)+N2/2)/100)) -> 0.81414263 | R2: =IF(ISBLANK(Q2),,IF(Q2>=0.975,"A+",IF(Q2>=0.925,"A",IF(Q2>=0.895,"A-",IF(Q2>=0.865,"B+",IF(Q2>=0.825,"B",IF(Q2>=0.795,"B-",IF(Q2>=0.765,"C+",IF(Q2>=0.725,"C",IF(Q2>=0.695,"C-",IF(Q2>=0.665,"D+",IF(Q2>=0.625,"D",IF(Q2>=0.595,"D-",IF(Q2<0.6,"F")))))))))))))) -> B- | S2: =IF(IF(H2=0,,IF(ISBLANK(AC2),,1-(((AE2/2+N2/2)-(AD2*2))/100)))>1, 1, IF(H2=0,,IF(ISBLANK(AC2),,1-(((AE2/2+N2/2)-(AD2*2))/100)))) -> 0.79 | T2: =IF(ISBLANK(S2),,IF(S2>=0.975,"A+",IF(S2>=0.925,"A",IF(S2>=0.895,"A-",IF(S2>=0.865,"B+",IF(S2>=0.825,"B",IF(S2>=0.795,"B-",IF(S2>=0.765,"C+",IF(S2>=0.725,"C",IF(S2>=0.695,"C-",IF(S2>=0.665,"D+",IF(S2>=0.625,"D",IF(S2>=0.595,"D-",IF(S2<0.6,"F")))))))))))))) -> C+ | U2: No | V2: =IF(ISBLANK(C2),,IFERROR(IF(VLOOKUP(B2,Standings!$A:$F, 6, 0)=VLOOKUP(C2,Standings!$A:$F, 6, 0), VLOOKUP(B2,Standings!$A:$F, 6, 0), "Non-con"), "FCS")) -> ACC | W2: =IF(ISBLANK(O2),,IF(O2>0,C2,B2)) -> Wake Forest | X2: =IF(ISBLANK(O2),,IF(O2<0,C2,B2)) -> Clemson | Y2: =IF(D2=0,,IF(ISBLANK(Q2),,VLOOKUP(X2,Week1,2,FALSE)/(VLOOKUP(X2,Week1,2,FALSE)+VLOOKUP(W2,Week1,2,FALSE))+0.05)*100) -> 92.287974 | Z2: Clemson | AA2: 37 | AB2: =IF(Z2<>"",(IF(Z2=B2, C2, B2)),"") -> Wake Forest | AC2: 13 | AE2: =IF(ISBLANK(AC2),,AA2-AC2) -> 24 | AG2: =IF(ISBLANK(S2),,If(X2=Z2, 1, 0)) -> 1
A3: 2 | B3: Duke | C3: Notre Dame | D3: =IFERROR(VLOOKUP(B3,Week1,2,FALSE),0) -> 6.67 | E3: =IF(ISBLANK(B3),,IFERROR(VLOOKUP(B3,CurrentRank!$B$2:$C$132,2,FALSE),0)) -> 28.66 | F3: =IFERROR(VLOOKUP(B3,Week1,3,FALSE),130) -> 35 | G3: =IF(ISBLANK(B3),,IFERROR(VLOOKUP(B3,CurrentRank!$B$2:$D$132,3,FALSE),130)) -> 120 | H3: =IFERROR(VLOOKUP(C3,Week1,2,FALSE),0) -> 36.88 | I3: =IF(ISBLANK(B3),,IFERROR(VLOOKUP(C3,CurrentRank!$B$2:$C$132,2,FALSE),0)) -> 78.79 | J3: =IFERROR(VLOOKUP(C3,Week1,3,FALSE),130) -> 10 | K3: =IF(ISBLANK(C3),,IFERROR(VLOOKUP(C3,CurrentRank!$B$2:$D$132,3,FALSE),130)) -> 7 | L3: =IF(U3= "Yes", 0, IF(ISBLANK(C3),,(D3+H3)*0.015)) -> 0.65325 | M3: =IF(U3= "Yes", 0, IF(ISBLANK(D3),,(E3+I3)*0.015)) -> 1.61175 | N3: =IF(ISBLANK(C3),,(F3+J3)/2) -> 22.5 | O3: =IF(H3=0,,(D3-(H3+L3))/2) -> -15.431625 | P3: =IF(ISBLANK(C3),,(E3-(I3+L3))/2) -> -25.391625 | Q3: =IF(ISBLANK(O3),,1-((ABS(O3/2)+N3/2)/100)) -> 0.81034187 | R3: =IF(ISBLANK(Q3),,IF(Q3>=0.975,"A+",IF(Q3>=0.925,"A",IF(Q3>=0.895,"A-",IF(Q3>=0.865,"B+",IF(Q3>=0.825,"B",IF(Q3>=0.795,"B-",IF(Q3>=0.765,"C+",IF(Q3>=0.725,"C",IF(Q3>=0.695,"C-",IF(Q3>=0.665,"D+",IF(Q3>=0.625,"D",IF(Q3>=0.595,"D-",IF(Q3<0.6,"F")))))))))))))) -> B- | S3: =IF(IF(H3=0,,IF(ISBLANK(AC3),,1-(((AE3/2+N3/2)-(AD3*2))/100)))>1, 1, IF(H3=0,,IF(ISBLANK(AC3),,1-(((AE3/2+N3/2)-(AD3*2))/100)))) -> 0.8175 | T3: =IF(ISBLANK(S3),,IF(S3>=0.975,"A+",IF(S3>=0.925,"A",IF(S3>=0.895,"A-",IF(S3>=0.865,"B+",IF(S3>=0.825,"B",IF(S3>=0.795,"B-",IF(S3>=0.765,"C+",IF(S3>=0.725,"C",IF(S3>=0.695,"C-",IF(S3>=0.665,"D+",IF(S3>=0.625,"D",IF(S3>=0.595,"D-",IF(S3<0.6,"F")))))))))))))) -> B- | U3: No | V3: =IF(ISBLANK(C3),,IFERROR(IF(VLOOKUP(B3,Standings!$A:$F, 6, 0)=VLOOKUP(C3,Standings!$A:$F, 6, 0), VLOOKUP(B3,Standings!$A:$F, 6, 0), "Non-con"), "FCS")) -> ACC | W3: =IF(ISBLANK(O3),,IF(O3>0,C3,B3)) -> Duke | X3: =IF(ISBLANK(O3),,IF(O3<0,C3,B3)) -> Notre Dame | Y3: =IF(D3=0,,IF(ISBLANK(Q3),,VLOOKUP(X3,Week1,2,FALSE)/(VLOOKUP(X3,Week1,2,FALSE)+VLOOKUP(W3,Week1,2,FALSE))+0.05)*100) -> 89.684271 | Z3: Notre Dame | AA3: 27 | AB3: =IF(Z3<>"",(IF(Z3=B3, C3, B3)),"") -> Duke | AC3: 13 | AE3: =IF(ISBLANK(AC3),,AA3-AC3) -> 14 | AG3: =IF(ISBLANK(S3),,If(X3=Z3, 1, 0)) -> 1
A4: 2 | B4: Tulsa | C4: Oklahoma State | D4: =IFERROR(VLOOKUP(B4,Week1,2,FALSE),0) -> 6.67 | E4: =IF(ISBLANK(B4),,IFERROR(VLOOKUP(B4,CurrentRank!$B$2:$C$132,2,FALSE),0)) -> 37.38 | F4: =IFERROR(VLOOKUP(B4,Week1,3,FALSE),130) -> 35 | G4: =IF(ISBLANK(B4),,IFERROR(VLOOKUP(B4,CurrentRank!$B$2:$D$132,3,FALSE),130)) -> 43 | H4: =IFERROR(VLOOKUP(C4,Week1,2,FALSE),0) -> 30.49 | I4: =IF(ISBLANK(B4),,IFERROR(VLOOKUP(C4,CurrentRank!$B$2:$C$132,2,FALSE),0)) -> 59.34 | J4: =IFERROR(VLOOKUP(C4,Week1,3,FALSE),130) -> 16 | K4: =IF(ISBLANK(C4),,IFERROR(VLOOKUP(C4,CurrentRank!$B$2:$D$132,3,FALSE),130)) -> 22 | L4: =IF(U4= "Yes", 0, IF(ISBLANK(C4),,(D4+H4)*0.015)) -> 0.5574 | M4: =IF(U4= "Yes", 0, IF(ISBLANK(D4),,(E4+I4)*0.015)) -> 1.4508 | N4: =IF(ISBLANK(C4),,(F4+J4)/2) -> 25.5 | O4: =IF(H4=0,,(D4-(H4+L4))/2) -> -12.1887 | P4: =IF(ISBLANK(C4),,(E4-(I4+L4))/2) -> -11.2587 | Q4: =IF(ISBLANK(O4),,1-((ABS(O4/2)+N4/2)/100)) -> 0.8115565 | R4: =IF(ISBLANK(Q4),,IF(Q4>=0.975,"A+",IF(Q4>=0.925,"A",IF(Q4>=0.895,"A-",IF(Q4>=0.865,"B+",IF(Q4>=0.825,"B",IF(Q4>=0.795,"B-",IF(Q4>=0.765,"C+",IF(Q4>=0.725,"C",IF(Q4>=0.695,"C-",IF(Q4>=0.665,"D+",IF(Q4>=0.625,"D",IF(Q4>=0.595,"D-",IF(Q4<0.6,"F")))))))))))))) -> B- | S4: =IF(IF(H4=0,,IF(ISBLANK(AC4),,1-(((AE4/2+N4/2)-(AD4*2))/100)))>1, 1, IF(H4=0,,IF(ISBLANK(AC4),,1-(((AE4/2+N4/2)-(AD4*2))/100)))) -> 0.8275 | T4: =IF(ISBLANK(S4),,IF(S4>=0.975,"A+",IF(S4>=0.925,"A",IF(S4>=0.895,"A-",IF(S4>=0.865,"B+",IF(S4>=0.825,"B",IF(S4>=0.795,"B-",IF(S4>=0.765,"C+",IF(S4>=0.725,"C",IF(S4>=0.695,"C-",IF(S4>=0.665,"D+",IF(S4>=0.625,"D",IF(S4>=0.595,"D-",IF(S4<0.6,"F")))))))))))))) -> B | U4: No | V4: =IF(ISBLANK(C4),,IFERROR(IF(VLOOKUP(B4,Standings!$A:$F, 6, 0)=VLOOKUP(C4,Standings!$A:$F, 6, 0), VLOOKUP(B4,Standings!$A:$F, 6, 0), "Non-con"), "FCS")) -> Non-con | W4: =IF(ISBLANK(O4),,IF(O4>0,C4,B4)) -> Tulsa | X4: =IF(ISBLANK(O4),,IF(O4<0,C4,B4)) -> Oklahoma State | Y4: =IF(D4=0,,IF(ISBLANK(Q4),,VLOOKUP(X4,Week1,2,FALSE)/(VLOOKUP(X4,Week1,2,FALSE)+VLOOKUP(W4,Week1,2,FALSE))+0.05)*100) -> 87.050592 | Z4: Oklahoma State | AA4: 16 | AB4: =IF(Z4<>"",(IF(Z4=B4, C4, B4)),"") -> Tulsa | AC4: 7 | AE4: =IF(ISBLANK(AC4),,AA4-AC4) -> 9 | AG4: =IF(ISBLANK(S4),,If(X4=Z4, 1, 0)) -> 1
A5: 2 | B5: Syracuse | C5: North Carolina | D5: =IFERROR(VLOOKUP(B5,Week1,2,FALSE),0) -> 6.67 | E5: =IF(ISBLANK(B5),,IFERROR(VLOOKUP(B5,CurrentRank!$B$2:$C$132,2,FALSE),0)) -> 26.74 | F5: =IFERROR(VLOOKUP(B5,Week1,3,FALSE),130) -> 35 | G5: =IF(ISBLANK(B5),,IFERROR(VLOOKUP(B5,CurrentRank!$B$2:$D$132,3,FALSE),130)) -> 123 | H5: =IFERROR(VLOOKUP(C5,Week1,2,FALSE),0) -> 28.08 | I5: =IF(ISBLANK(B5),,IFERROR(VLOOKUP(C5,CurrentRank!$B$2:$C$132,2,FALSE),0)) -> 63.1 | J5: =IFERROR(VLOOKUP(C5,Week1,3,FALSE),130) -> 19 | K5: =IF(ISBLANK(C5),,IFERROR(VLOOKUP(C5,CurrentRank!$B$2:$D$132,3,FALSE),130)) -> 18 | L5: =IF(U5= "Yes", 0, IF(ISBLANK(C5),,(D5+H5)*0.015)) -> 0.52125 | M5: =IF(U5= "Yes", 0, IF(ISBLANK(D5),,(E5+I5)*0.015)) -> 1.3476 | N5: =IF(ISBLANK(C5),,(F5+J5)/2) -> 27 | O5: =IF(H5=0,,(D5-(H5+L5))/2) -> -10.965625 | P5: =IF(ISBLANK(C5),,(E5-(I5+L5))/2) -> -18.440625 | Q5: =IF(ISBLANK(O5),,1-((ABS(O5/2)+N5/2)/100)) -> 0.81017187 | R5: =IF(ISBLANK(Q5),,IF(Q5>=0.975,"A+",IF(Q5>=0.925,"A",IF(Q5>=0.895,"A-",IF(Q5>=0.865,"B+",IF(Q5>=0.825,"B",IF(Q5>=0.795,"B-",IF(Q5>=0.765,"C+",IF(Q5>=0.725,"C",IF(Q5>=0.695,"C-",IF(Q5>=0.665,"D+",IF(Q5>=0.625,"D",IF(Q5>=0.595,"D-",IF(Q5<0.6,"F")))))))))))))) -> B- | S5: =IF(IF(H5=0,,IF(ISBLANK(AC5),,1-(((AE5/2+N5/2)-(AD5*2))/100)))>1, 1, IF(H5=0,,IF(ISBLANK(AC5),,1-(((AE5/2+N5/2)-(AD5*2))/100)))) -> 0.74 | T5: =IF(ISBLANK(S5),,IF(S5>=0.975,"A+",IF(S5>=0.925,"A",IF(S5>=0.895,"A-",IF(S5>=0.865,"B+",IF(S5>=0.825,"B",IF(S5>=0.795,"B-",IF(S5>=0.765,"C+",IF(S5>=0.725,"C",IF(S5>=0.695,"C-",IF(S5>=0.665,"D+",IF(S5>=0.625,"D",IF(S5>=0.595,"D-",IF(S5<0.6,"F")))))))))))))) -> C | U5: No | V5: =IF(ISBLANK(C5),,IFERROR(IF(VLOOKUP(B5,Standings!$A:$F, 6, 0)=VLOOKUP(C5,Standings!$A:$F, 6, 0), VLOOKUP(B5,Standings!$A:$F, 6, 0), "Non-con"), "FCS")) -> ACC | W5: =IF(ISBLANK(O5),,IF(O5>0,C5,B5)) -> Syracuse | X5: =IF(ISBLANK(O5),,IF(O5<0,C5,B5)) -> North Carolina | Y5: =IF(D5=0,,IF(ISBLANK(Q5),,VLOOKUP(X5,Week1,2,FALSE)/(VLOOKUP(X5,Week1,2,FALSE)+VLOOKUP(W5,Week1,2,FALSE))+0.05)*100) -> 85.805755 | Z5: North Carolina | AA5: 31 | AB5: =IF(Z5<>"",(IF(Z5=B5, C5, B5)),"") -> Syracuse | AC5: 6 | AE5: =IF(ISBLANK(AC5),,AA5-AC5) -> 25 | AG5: =IF(ISBLANK(S5),,If(X5=Z5, 1, 0)) -> 1
A6: 5 | B6: South Florida | C6: Cincinnati | D6: =IFERROR(VLOOKUP(B6,Week4,2,FALSE),0) -> 18.3 | E6: =IF(ISBLANK(B6),,IFERROR(VLOOKUP(B6,CurrentRank!$B$2:$C$132,2,FALSE),0)) -> 13.91 | F6: =IFERROR(VLOOKUP(B6,Week4,3,FALSE),130) -> 130 | G6: =IF(ISBLANK(B6),,IFERROR(VLOOKUP(B6,CurrentRank!$B$2:$D$132,3,FALSE),130)) -> 129 | H6: =IFERROR(VLOOKUP(C6,Week4,2,FALSE),0) -> 69.04 | I6: =IF(ISBLANK(B6),,IFERROR(VLOOKUP(C6,CurrentRank!$B$2:$C$132,2,FALSE),0)) -> 72.9 | J6: =IFERROR(VLOOKUP(C6,Week4,3,FALSE),130) -> 11 | K6: =IF(ISBLANK(C6),,IFERROR(VLOOKUP(C6,CurrentRank!$B$2:$D$132,3,FALSE),130)) -> 9 | L6: =IF(U6= "Yes", 0, IF(ISBLANK(C6),,(D6+H6)*0.015)) -> 1.3101 | M6: =IF(U6= "Yes", 0, IF(ISBLANK(D6),,(E6+I6)*0.015)) -> 1.30215 | N6: =IF(ISBLANK(C6),,(F6+J6)/2) -> 70.5 | O6: =IF(H6=0,,(D6-(H6+L6))/2) -> -26.02505 | P6: =IF(ISBLANK(C6),,(E6-(I6+L6))/2) -> -30.15005 | Q6: =IF(ISBLANK(O6),,1-((ABS(O6/2)+N6/2)/100)) -> 0.51737475 | R6: =IF(ISBLANK(Q6),,IF(Q6>=0.975,"A+",IF(Q6>=0.925,"A",IF(Q6>=0.895,"A-",IF(Q6>=0.865,"B+",IF(Q6>=0.825,"B",IF(Q6>=0.795,"B-",IF(Q6>=0.765,"C+",IF(Q6>=0.725,"C",IF(Q6>=0.695,"C-",IF(Q6>=0.665,"D+",IF(Q6>=0.625,"D",IF(Q6>=0.595,"D-",IF(Q6<0.6,"F")))))))))))))) -> F | S6: =IF(IF(H6=0,,IF(ISBLANK(AC6),,1-(((AE6/2+N6/2)-(AD6*2))/100)))>1, 1, IF(H6=0,,IF(ISBLANK(AC6),,1-(((AE6/2+N6/2)-(AD6*2))/100)))) -> 0.5425 | T6: =IF(ISBLANK(S6),,IF(S6>=0.975,"A+",IF(S6>=0.925,"A",IF(S6>=0.895,"A-",IF(S6>=0.865,"B+",IF(S6>=0.825,"B",IF(S6>=0.795,"B-",IF(S6>=0.765,"C+",IF(S6>=0.725,"C",IF(S6>=0.695,"C-",IF(S6>=0.665,"D+",IF(S6>=0.625,"D",IF(S6>=0.595,"D-",IF(S6<0.6,"F")))))))))))))) -> F | U6: No | V6: =IF(ISBLANK(C6),,IFERROR(IF(VLOOKUP(B6,Standings!$A:$F, 6, 0)=VLOOKUP(C6,Standings!$A:$F, 6, 0), VLOOKUP(B6,Standings!$A:$F, 6, 0), "Non-con"), "FCS")) -> AAC | W6: =IF(ISBLANK(O6),,IF(O6>0,C6,B6)) -> South Florida | X6: =IF(ISBLANK(O6),,IF(O6<0,C6,B6)) -> Cincinnati | Y6: =IF(D6=0,,IF(ISBLANK(Q6),,VLOOKUP(X6,Week4,2,FALSE)/(VLOOKUP(X6,Week4,2,FALSE)+VLOOKUP(W6,Week4,2,FALSE))+0.05)*100) -> 84.047401 | Z6: Cincinnati | AA6: 28 | AB6: =IF(Z6<>"",(IF(Z6=B6, C6, B6)),"") -> South Florida | AC6: 7 | AE6: =IF(ISBLANK(AC6),,AA6-AC6) -> 21 | AG6: =IF(ISBLANK(S6),,If(X6=Z6, 1, 0)) -> 1
A7: 14 | B7: Syracuse | C7: Notre Dame | D7: =IFERROR(VLOOKUP(B7,Week13,2,FALSE),0) -> 25.45 | E7: =IF(ISBLANK(B7),,IFERROR(VLOOKUP(B7,CurrentRank!$B$2:$C$132,2,FALSE),0)) -> 26.74 | F7: =IFERROR(VLOOKUP(B7,Week13,3,FALSE),130) -> 123 | G7: =IF(ISBLANK(B7),,IFERROR(VLOOKUP(B7,CurrentRank!$B$2:$D$132,3,FALSE),130)) -> 123 | H7: =IFERROR(VLOOKUP(C7,Week13,2,FALSE),0) -> 90.44 | I7: =IF(ISBLANK(B7),,IFERROR(VLOOKUP(C7,CurrentRank!$B$2:$C$132,2,FALSE),0)) -> 78.79 | J7: =IFERROR(VLOOKUP(C7,Week13,3,FALSE),130) -> 2 | K7: =IF(ISBLANK(C7),,IFERROR(VLOOKUP(C7,CurrentRank!$B$2:$D$132,3,FALSE),130)) -> 7 | L7: =IF(U7= "Yes", 0, IF(ISBLANK(C7),,(D7+H7)*0.015)) -> 1.73835 | M7: =IF(U7= "Yes", 0, IF(ISBLANK(D7),,(E7+I7)*0.015)) -> 1.58295 | N7: =IF(ISBLANK(C7),,(F7+J7)/2) -> 62.5 | O7: =IF(H7=0,,(D7-(H7+L7))/2) -> -33.364175 | P7: =IF(ISBLANK(C7),,(E7-(I7+L7))/2) -> -26.894175 | Q7: =IF(ISBLANK(O7),,1-((ABS(O7/2)+N7/2)/100)) -> 0.52067913 | R7: =IF(ISBLANK(Q7),,IF(Q7>=0.975,"A+",IF(Q7>=0.925,"A",IF(Q7>=0.895,"A-",IF(Q7>=0.865,"B+",IF(Q7>=0.825,"B",IF(Q7>=0.795,"B-",IF(Q7>=0.765,"C+",IF(Q7>=0.725,"C",IF(Q7>=0.695,"C-",IF(Q7>=0.665,"D+",IF(Q7>=0.625,"D",IF(Q7>=0.595,"D-",IF(Q7<0.6,"F")))))))))))))) -> F | S7: =IF(IF(H7=0,,IF(ISBLANK(AC7),,1-(((AE7/2+N7/2)-(AD7*2))/100)))>1, 1, IF(H7=0,,IF(ISBLANK(AC7),,1-(((AE7/2+N7/2)-(AD7*2))/100)))) -> 0.5675 | T7: =IF(ISBLANK(S7),,IF(S7>=0.975,"A+",IF(S7>=0.925,"A",IF(S7>=0.895,"A-",IF(S7>=0.865,"B+",IF(S7>=0.825,"B",IF(S7>=0.795,"B-",IF(S7>=0.765,"C+",IF(S7>=0.725,"C",IF(S7>=0.695,"C-",IF(S7>=0.665,"D+",IF(S7>=0.625,"D",IF(S7>=0.595,"D-",IF(S7<0.6,"F")))))))))))))) -> F | U7: No | V7: =IF(ISBLANK(C7),,IFERROR(IF(VLOOKUP(B7,Standings!$A:$F, 6, 0)=VLOOKUP(C7,Standings!$A:$F, 6, 0), VLOOKUP(B7,Standings!$A:$F, 6, 0), "Non-con"), "FCS")) -> ACC | W7: =IF(ISBLANK(O7),,IF(O7>0,C7,B7)) -> Syracuse | X7: =IF(ISBLANK(O7),,IF(O7<0,C7,B7)) -> Notre Dame | Y7: =IF(D7=0,,IF(ISBLANK(Q7),,VLOOKUP(X7,Week13,2,FALSE)/(VLOOKUP(X7,Week13,2,FALSE)+VLOOKUP(W7,Week13,2,FALSE))+0.05)*100) -> 83.03952 | Z7: Notre Dame | AA7: 45 | AB7: =IF(Z7<>"",(IF(Z7=B7, C7, B7)),"") -> Syracuse | AC7: 21 | AE7: =IF(ISBLANK(AC7),,AA7-AC7) -> 24 | AG7: =IF(ISBLANK(S7),,If(X7=Z7, 1, 0)) -> 1 | AJ7: BYU
A8: 10 | B8: Clemson | C8: Notre Dame | D8: =IFERROR(VLOOKUP(B8,Week9,2,FALSE),0) -> 94.26 | E8: =IF(ISBLANK(B8),,IFERROR(VLOOKUP(B8,CurrentRank!$B$2:$C$132,2,FALSE),0)) -> 84.24 | F8: =IFERROR(VLOOKUP(B8,Week9,3,FALSE),130) -> 1 | G8: =IF(ISBLANK(B8),,IFERROR(VLOOKUP(B8,CurrentRank!$B$2:$D$132,3,FALSE),130)) -> 4 | H8: =IFERROR(VLOOKUP(C8,Week9,2,FALSE),0) -> 86.91 | I8: =IF(ISBLANK(B8),,IFERROR(VLOOKUP(C8,CurrentRank!$B$2:$C$132,2,FALSE),0)) -> 78.79 | J8: =IFERROR(VLOOKUP(C8,Week9,3,FALSE),130) -> 3 | K8: =IF(ISBLANK(C8),,IFERROR(VLOOKUP(C8,CurrentRank!$B$2:$D$132,3,FALSE),130)) -> 7 | L8: =IF(U8= "Yes", 0, IF(ISBLANK(C8),,(D8+H8)*0.015)) -> 2.71755 | M8: =IF(U8= "Yes", 0, IF(ISBLANK(D8),,(E8+I8)*0.015)) -> 2.44545 | N8: =IF(ISBLANK(C8),,(F8+J8)/2) -> 2 | O8: =IF(H8=0,,(D8-(H8+L8))/2) -> 2.316225 | P8: =IF(ISBLANK(C8),,(E8-(I8+L8))/2) -> 1.366225 | Q8: =IF(ISBLANK(O8),,1-((ABS(O8/2)+N8/2)/100)) -> 0.97841888 | R8: =IF(ISBLANK(Q8),,IF(Q8>=0.975,"A+",IF(Q8>=0.925,"A",IF(Q8>=0.895,"A-",IF(Q8>=0.865,"B+",IF(Q8>=0.825,"B",IF(Q8>=0.795,"B-",IF(Q8>=0.765,"C+",IF(Q8>=0.725,"C",IF(Q8>=0.695,"C-",IF(Q8>=0.665,"D+",IF(Q8>=0.625,"D",IF(Q8>=0.595,"D-",IF(Q8<0.6,"F")))))))))))))) -> A+ | S8: =IF(IF(H8=0,,IF(ISBLANK(AC8),,1-(((AE8/2+N8/2)-(AD8*2))/100)))>1, 1, IF(H8=0,,IF(ISBLANK(AC8),,1-(((AE8/2+N8/2)-(AD8*2))/100)))) -> 0.975 | T8: =IF(ISBLANK(S8),,IF(S8>=0.975,"A+",IF(S8>=0.925,"A",IF(S8>=0.895,"A-",IF(S8>=0.865,"B+",IF(S8>=0.825,"B",IF(S8>=0.795,"B-",IF(S8>=0.765,"C+",IF(S8>=0.725,"C",IF(S8>=0.695,"C-",IF(S8>=0.665,"D+",IF(S8>=0.625,"D",IF(S8>=0.595,"D-",IF(S8<0.6,"F")))))))))))))) -> A+ | U8: No | V8: =IF(ISBLANK(C8),,IFERROR(IF(VLOOKUP(B8,Standings!$A:$F, 6, 0)=VLOOKUP(C8,Standings!$A:$F, 6, 0), VLOOKUP(B8,Standings!$A:$F, 6, 0), "Non-con"), "FCS")) -> ACC | W8: =IF(ISBLANK(O8),,IF(O8>0,C8,B8)) -> Notre Dame | X8: =IF(ISBLANK(O8),,IF(O8<0,C8,B8)) -> Clemson | Y8: =IF(D8=0,,IF(ISBLANK(Q8),,VLOOKUP(X8,Week9,2,FALSE)/(VLOOKUP(X8,Week9,2,FALSE)+VLOOKUP(W8,Week9,2,FALSE))+0.05)*100) -> 57.028482 | Z8: Notre Dame | AA8: 47 | AB8: =IF(Z8<>"",(IF(Z8=B8, C8, B8)),"") -> Clemson | AC8: 40 | AD8: 1 | AE8: =IF(ISBLANK(AC8),,AA8-AC8) -> 7 | AG8: =IF(ISBLANK(S8),,If(X8=Z8, 1, 0)) -> 0 | AH8: =IF(ISBLANK(S8),,IF(X8=Z8, 1, 0)) -> 0
A9: 5 | B9: Oklahoma State | C9: Kansas | D9: =IFERROR(VLOOKUP(B9,Week4,2,FALSE),0) -> 67.72 | E9: =IF(ISBLANK(B9),,IFERROR(VLOOKUP(B9,CurrentRank!$B$2:$C$132,2,FALSE),0)) -> 59.34 | F9: =IFERROR(VLOOKUP(B9,Week4,3,FALSE),130) -> 12 | G9: =IF(ISBLANK(B9),,IFERROR(VLOOKUP(B9,CurrentRank!$B$2:$D$132,3,FALSE),130)) -> 22 | H9: =IFERROR(VLOOKUP(C9,Week4,2,FALSE),0) -> 19.44 | I9: =IF(ISBLANK(B9),,IFERROR(VLOOKUP(C9,CurrentRank!$B$2:$C$132,2,FALSE),0)) -> 21.55 | J9: =IFERROR(VLOOKUP(C9,Week4,3,FALSE),130) -> 129 | K9: =IF(ISBLANK(C9),,IFERROR(VLOOKUP(C9,CurrentRank!$B$2:$D$132,3,FALSE),130)) -> 127 | L9: =IF(U9= "Yes", 0, IF(ISBLANK(C9),,(D9+H9)*0.015)) -> 1.3074 | M9: =IF(U9= "Yes", 0, IF(ISBLANK(D9),,(E9+I9)*0.015)) -> 1.21335 | N9: =IF(ISBLANK(C9),,(F9+J9)/2) -> 70.5 | O9: =IF(H9=0,,(D9-(H9+L9))/2) -> 23.4863 | P9: =IF(ISBLANK(C9),,(E9-(I9+L9))/2) -> 18.2413 | Q9: =IF(ISBLANK(O9),,1-((ABS(O9/2)+N9/2)/100)) -> 0.5300685 | R9: =IF(ISBLANK(Q9),,IF(Q9>=0.975,"A+",IF(Q9>=0.925,"A",IF(Q9>=0.895,"A-",IF(Q9>=0.865,"B+",IF(Q9>=0.825,"B",IF(Q9>=0.795,"B-",IF(Q9>=0.765,"C+",IF(Q9>=0.725,"C",IF(Q9>=0.695,"C-",IF(Q9>=0.665,"D+",IF(Q9>=0.625,"D",IF(Q9>=0.595,"D-",IF(Q9<0.6,"F")))))))))))))) -> F | S9: =IF(IF(H9=0,,IF(ISBLANK(AC9),,1-(((AE9/2+N9/2)-(AD9*2))/100)))>1, 1, IF(H9=0,,IF(ISBLANK(AC9),,1-(((AE9/2+N9/2)-(AD9*2))/100)))) -> 0.4475 | T9: =IF(ISBLANK(S9),,IF(S9>=0.975,"A+",IF(S9>=0.925,"A",IF(S9>=0.895,"A-",IF(S9>=0.865,"B+",IF(S9>=0.825,"B",IF(S9>=0.795,"B-",IF(S9>=0.765,"C+",IF(S9>=0.725,"C",IF(S9>=0.695,"C-",IF(S9>=0.665,"D+",IF(S9>=0.625,"D",IF(S9>=0.595,"D-",IF(S9<0.6,"F")))))))))))))) -> F | U9: No | V9: =IF(ISBLANK(C9),,IFERROR(IF(VLOOKUP(B9,Standings!$A:$F, 6, 0)=VLOOKUP(C9,Standings!$A:$F, 6, 0), VLOOKUP(B9,Standings!$A:$F, 6, 0), "Non-con"), "FCS")) -> BIG12 | W9: =IF(ISBLANK(O9),,IF(O9>0,C9,B9)) -> Kansas | X9: =IF(ISBLANK(O9),,IF(O9<0,C9,B9)) -> Oklahoma State | Y9: =IF(D9=0,,IF(ISBLANK(Q9),,VLOOKUP(X9,Week4,2,FALSE)/(VLOOKUP(X9,Week4,2,FALSE)+VLOOKUP(W9,Week4,2,FALSE))+0.05)*100) -> 82.696191 | Z9: Oklahoma State | AA9: 47 | AB9: =IF(Z9<>"",(IF(Z9=B9, C9, B9)),"") -> Kansas | AC9: 7 | AE9: =IF(ISBLANK(AC9),,AA9-AC9) -> 40 | AG9: =IF(ISBLANK(S9),,If(X9=Z9, 1, 0)) -> 1
A10: 8 | B10: Syracuse | C10: Clemson | D10: =IFERROR(VLOOKUP(B10,Week7,2,FALSE),0) -> 28.46 | E10: =IF(ISBLANK(B10),,IFERROR(VLOOKUP(B10,CurrentRank!$B$2:$C$132,2,FALSE),0)) -> 26.74 | F10: =IFERROR(VLOOKUP(B10,Week7,3,FALSE),130) -> 122 | G10: =IF(ISBLANK(B10),,IFERROR(VLOOKUP(B10,CurrentRank!$B$2:$D$132,3,FALSE),130)) -> 123 | H10: =IFERROR(VLOOKUP(C10,Week7,2,FALSE),0) -> 95.81 | I10: =IF(ISBLANK(B10),,IFERROR(VLOOKUP(C10,CurrentRank!$B$2:$C$132,2,FALSE),0)) -> 84.24 | J10: =IFERROR(VLOOKUP(C10,Week7,3,FALSE),130) -> 1 | K10: =IF(ISBLANK(C10),,IFERROR(VLOOKUP(C10,CurrentRank!$B$2:$D$132,3,FALSE),130)) -> 4 | L10: =IF(U10= "Yes", 0, IF(ISBLANK(C10),,(D10+H10)*0.015)) -> 1.86405 | M10: =IF(U10= "Yes", 0, IF(ISBLANK(D10),,(E10+I10)*0.015)) -> 1.6647 | N10: =IF(ISBLANK(C10),,(F10+J10)/2) -> 61.5 | O10: =IF(H10=0,,(D10-(H10+L10))/2) -> -34.607025 | P10: =IF(ISBLANK(C10),,(E10-(I10+L10))/2) -> -29.682025 | Q10: =IF(ISBLANK(O10),,1-((ABS(O10/2)+N10/2)/100)) -> 0.51946488 | R10: =IF(ISBLANK(Q10),,IF(Q10>=0.975,"A+",IF(Q10>=0.925,"A",IF(Q10>=0.895,"A-",IF(Q10>=0.865,"B+",IF(Q10>=0.825,"B",IF(Q10>=0.795,"B-",IF(Q10>=0.765,"C+",IF(Q10>=0.725,"C",IF(Q10>=0.695,"C-",IF(Q10>=0.665,"D+",IF(Q10>=0.625,"D",IF(Q10>=0.595,"D-",IF(Q10<0.6,"F")))))))))))))) -> F | S10: =IF(IF(H10=0,,IF(ISBLANK(AC10),,1-(((AE10/2+N10/2)-(AD10*2))/100)))>1, 1, IF(H10=0,,IF(ISBLANK(AC10),,1-(((AE10/2+N10/2)-(AD10*2))/100)))) -> 0.5625 | T10: =IF(ISBLANK(S10),,IF(S10>=0.975,"A+",IF(S10>=0.925,"A",IF(S10>=0.895,"A-",IF(S10>=0.865,"B+",IF(S10>=0.825,"B",IF(S10>=0.795,"B-",IF(S10>=0.765,"C+",IF(S10>=0.725,"C",IF(S10>=0.695,"C-",IF(S10>=0.665,"D+",IF(S10>=0.625,"D",IF(S10>=0.595,"D-",IF(S10<0.6,"F")))))))))))))) -> F | U10: No | V10: =IF(ISBLANK(C10),,IFERROR(IF(VLOOKUP(B10,Standings!$A:$F, 6, 0)=VLOOKUP(C10,Standings!$A:$F, 6, 0), VLOOKUP(B10,Standings!$A:$F, 6, 0), "Non-con"), "FCS")) -> ACC | W10: =IF(ISBLANK(O10),,IF(O10>0,C10,B10)) -> Syracuse | X10: =IF(ISBLANK(O10),,IF(O10<0,C10,B10)) -> Clemson | Y10: =IF(D10=0,,IF(ISBLANK(Q10),,VLOOKUP(X10,Week7,2,FALSE)/(VLOOKUP(X10,Week7,2,FALSE)+VLOOKUP(W10,Week7,2,FALSE))+0.05)*100) -> 82.098254 | Z10: Clemson | AA10: 47 | AB10: =IF(Z10<>"",(IF(Z10=B10, C10, B10)),"") -> Syracuse | AC10: 21 | AE10: =IF(ISBLANK(AC10),,AA10-AC10) -> 26 | AG10: =IF(ISBLANK(S10),,If(X10=Z10, 1, 0)) -> 1
A11: 13 | B11: Central Florida | C11: South Florida | D11: =IFERROR(VLOOKUP(B11,Week12,2,FALSE),0) -> 40.27 | E11: =IF(ISBLANK(B11),,IFERROR(VLOOKUP(B11,CurrentRank!$B$2:$C$132,2,FALSE),0)) -> 41.86 | F11: =IFERROR(VLOOKUP(B11,Week12,3,FALSE),130) -> 39 | G11: =IF(ISBLANK(B11),,IFERROR(VLOOKUP(B11,CurrentRank!$B$2:$D$132,3,FALSE),130)) -> 30 | H11: =IFERROR(VLOOKUP(C11,Week12,2,FALSE),0) -> 12.09 | I11: =IF(ISBLANK(B11),,IFERROR(VLOOKUP(C11,CurrentRank!$B$2:$C$132,2,FALSE),0)) -> 13.91 | J11: =IFERROR(VLOOKUP(C11,Week12,3,FALSE),130) -> 129 | K11: =IF(ISBLANK(C11),,IFERROR(VLOOKUP(C11,CurrentRank!$B$2:$D$132,3,FALSE),130)) -> 129 | L11: =IF(U11= "Yes", 0, IF(ISBLANK(C11),,(D11+H11)*0.015)) -> 0.7854 | M11: =IF(U11= "Yes", 0, IF(ISBLANK(D11),,(E11+I11)*0.015)) -> 0.83655 | N11: =IF(ISBLANK(C11),,(F11+J11)/2) -> 84 | O11: =IF(H11=0,,(D11-(H11+L11))/2) -> 13.6973 | P11: =IF(ISBLANK(C11),,(E11-(I11+L11))/2) -> 13.5823 | Q11: =IF(ISBLANK(O11),,1-((ABS(O11/2)+N11/2)/100)) -> 0.5115135 | R11: =IF(ISBLANK(Q11),,IF(Q11>=0.975,"A+",IF(Q11>=0.925,"A",IF(Q11>=0.895,"A-",IF(Q11>=0.865,"B+",IF(Q11>=0.825,"B",IF(Q11>=0.795,"B-",IF(Q11>=0.765,"C+",IF(Q11>=0.725,"C",IF(Q11>=0.695,"C-",IF(Q11>=0.665,"D+",IF(Q11>=0.625,"D",IF(Q11>=0.595,"D-",IF(Q11<0.6,"F")))))))))))))) -> F | S11: =IF(IF(H11=0,,IF(ISBLANK(AC11),,1-(((AE11/2+N11/2)-(AD11*2))/100)))>1, 1, IF(H11=0,,IF(ISBLANK(AC11),,1-(((AE11/2+N11/2)-(AD11*2))/100)))) -> 0.52 | T11: =IF(ISBLANK(S11),,IF(S11>=0.975,"A+",IF(S11>=0.925,"A",IF(S11>=0.895,"A-",IF(S11>=0.865,"B+",IF(S11>=0.825,"B",IF(S11>=0.795,"B-",IF(S11>=0.765,"C+",IF(S11>=0.725,"C",IF(S11>=0.695,"C-",IF(S11>=0.665,"D+",IF(S11>=0.625,"D",IF(S11>=0.595,"D-",IF(S11<0.6,"F")))))))))))))) -> F | U11: No | V11: =IF(ISBLANK(C11),,IFERROR(IF(VLOOKUP(B11,Standings!$A:$F, 6, 0)=VLOOKUP(C11,Standings!$A:$F, 6, 0), VLOOKUP(B11,Standings!$A:$F, 6, 0), "Non-con"), "FCS")) -> AAC | W11: =IF(ISBLANK(O11),,IF(O11>0,C11,B11)) -> South Florida | X11: =IF(ISBLANK(O11),,IF(O11<0,C11,B11)) -> Central Florida | Y11: =IF(D11=0,,IF(ISBLANK(Q11),,VLOOKUP(X11,Week12,2,FALSE)/(VLOOKUP(X11,Week12,2,FALSE)+VLOOKUP(W11,Week12,2,FALSE))+0.05)*100) -> 81.909855 | Z11: Central Florida | AA11: 58 | AB11: =IF(Z11<>"",(IF(Z11=B11, C11, B11)),"") -> South Florida | AC11: 46 | AE11: =IF(ISBLANK(AC11),,AA11-AC11) -> 12 | AG11: =IF(ISBLANK(S11),,If(X11=Z11, 1, 0)) -> 1 | AJ11: Texas A&M
A12: 9 | B12: Notre Dame | C12: Georgia Tech | D12: =IFERROR(VLOOKUP(B12,Week8,2,FALSE),0) -> 86.13 | E12: =IF(ISBLANK(B12),,IFERROR(VLOOKUP(B12,CurrentRank!$B$2:$C$132,2,FALSE),0)) -> 78.79 | F12: =IFERROR(VLOOKUP(B12,Week8,3,FALSE),130) -> 3 | G12: =IF(ISBLANK(B12),,IFERROR(VLOOKUP(B12,CurrentRank!$B$2:$D$132,3,FALSE),130)) -> 7 | H12: =IFERROR(VLOOKUP(C12,Week8,2,FALSE),0) -> 26.51 | I12: =IF(ISBLANK(B12),,IFERROR(VLOOKUP(C12,CurrentRank!$B$2:$C$132,2,FALSE),0)) -> 30.15 | J12: =IFERROR(VLOOKUP(C12,Week8,3,FALSE),130) -> 121 | K12: =IF(ISBLANK(C12),,IFERROR(VLOOKUP(C12,CurrentRank!$B$2:$D$132,3,FALSE),130)) -> 109 | L12: =IF(U12= "Yes", 0, IF(ISBLANK(C12),,(D12+H12)*0.015)) -> 1.6896 | M12: =IF(U12= "Yes", 0, IF(ISBLANK(D12),,(E12+I12)*0.015)) -> 1.6341 | N12: =IF(ISBLANK(C12),,(F12+J12)/2) -> 62 | O12: =IF(H12=0,,(D12-(H12+L12))/2) -> 28.9652 | P12: =IF(ISBLANK(C12),,(E12-(I12+L12))/2) -> 23.4752 | Q12: =IF(ISBLANK(O12),,1-((ABS(O12/2)+N12/2)/100)) -> 0.545174 | R12: =IF(ISBLANK(Q12),,IF(Q12>=0.975,"A+",IF(Q12>=0.925,"A",IF(Q12>=0.895,"A-",IF(Q12>=0.865,"B+",IF(Q12>=0.825,"B",IF(Q12>=0.795,"B-",IF(Q12>=0.765,"C+",IF(Q12>=0.725,"C",IF(Q12>=0.695,"C-",IF(Q12>=0.665,"D+",IF(Q12>=0.625,"D",IF(Q12>=0.595,"D-",IF(Q12<0.6,"F")))))))))))))) -> F | S12: =IF(IF(H12=0,,IF(ISBLANK(AC12),,1-(((AE12/2+N12/2)-(AD12*2))/100)))>1, 1, IF(H12=0,,IF(ISBLANK(AC12),,1-(((AE12/2+N12/2)-(AD12*2))/100)))) -> 0.6 | T12: =IF(ISBLANK(S12),,IF(S12>=0.975,"A+",IF(S12>=0.925,"A",IF(S12>=0.895,"A-",IF(S12>=0.865,"B+",IF(S12>=0.825,"B",IF(S12>=0.795,"B-",IF(S12>=0.765,"C+",IF(S12>=0.725,"C",IF(S12>=0.695,"C-",IF(S12>=0.665,"D+",IF(S12>=0.625,"D",IF(S12>=0.595,"D-",IF(S12<0.6,"F")))))))))))))) -> D- | U12: No | V12: =IF(ISBLANK(C12),,IFERROR(IF(VLOOKUP(B12,Standings!$A:$F, 6, 0)=VLOOKUP(C12,Standings!$A:$F, 6, 0), VLOOKUP(B12,Standings!$A:$F, 6, 0), "Non-con"), "FCS")) -> ACC | W12: =IF(ISBLANK(O12),,IF(O12>0,C12,B12)) -> Georgia Tech | X12: =IF(ISBLANK(O12),,IF(O12<0,C12,B12)) -> Notre Dame | Y12: =IF(D12=0,,IF(ISBLANK(Q12),,VLOOKUP(X12,Week8,2,FALSE)/(VLOOKUP(X12,Week8,2,FALSE)+VLOOKUP(W12,Week8,2,FALSE))+0.05)*100) -> 81.464844 | Z12: Notre Dame | AA12: 31 | AB12: =IF(Z12<>"",(IF(Z12=B12, C12, B12)),"") -> Georgia Tech | AC12: 13 | AE12: =IF(ISBLANK(AC12),,AA12-AC12) -> 18 | AG12: =IF(ISBLANK(S12),,If(X12=Z12, 1, 0)) -> 1 | AJ12: Appalachian State
A13: 9 | B13: Mississippi State | C13: Alabama | D13: =IFERROR(VLOOKUP(B13,Week8,2,FALSE),0) -> 29.5 | E13: =IF(ISBLANK(B13),,IFERROR(VLOOKUP(B13,CurrentRank!$B$2:$C$132,2,FALSE),0)) -> 33.91 | F13: =IFERROR(VLOOKUP(B13,Week8,3,FALSE),130) -> 109 | G13: =IF(ISBLANK(B13),,IFERROR(VLOOKUP(B13,CurrentRank!$B$2:$D$132,3,FALSE),130)) -> 75 | H13: =IFERROR(VLOOKUP(C13,Week8,2,FALSE),0) -> 92.87 | I13: =IF(ISBLANK(B13),,IFERROR(VLOOKUP(C13,CurrentRank!$B$2:$C$132,2,FALSE),0)) -> 96.59 | J13: =IFERROR(VLOOKUP(C13,Week8,3,FALSE),130) -> 2 | K13: =IF(ISBLANK(C13),,IFERROR(VLOOKUP(C13,CurrentRank!$B$2:$D$132,3,FALSE),130)) -> 1 | L13: =IF(U13= "Yes", 0, IF(ISBLANK(C13),,(D13+H13)*0.015)) -> 1.83555 | M13: =IF(U13= "Yes", 0, IF(ISBLANK(D13),,(E13+I13)*0.015)) -> 1.9575 | N13: =IF(ISBLANK(C13),,(F13+J13)/2) -> 55.5 | O13: =IF(H13=0,,(D13-(H13+L13))/2) -> -32.602775 | P13: =IF(ISBLANK(C13),,(E13-(I13+L13))/2) -> -32.257775 | Q13: =IF(ISBLANK(O13),,1-((ABS(O13/2)+N13/2)/100)) -> 0.55948612 | R13: =IF(ISBLANK(Q13),,IF(Q13>=0.975,"A+",IF(Q13>=0.925,"A",IF(Q13>=0.895,"A-",IF(Q13>=0.865,"B+",IF(Q13>=0.825,"B",IF(Q13>=0.795,"B-",IF(Q13>=0.765,"C+",IF(Q13>=0.725,"C",IF(Q13>=0.695,"C-",IF(Q13>=0.665,"D+",IF(Q13>=0.625,"D",IF(Q13>=0.595,"D-",IF(Q13<0.6,"F")))))))))))))) -> F | S13: =IF(IF(H13=0,,IF(ISBLANK(AC13),,1-(((AE13/2+N13/2)-(AD13*2))/100)))>1, 1, IF(H13=0,,IF(ISBLANK(AC13),,1-(((AE13/2+N13/2)-(AD13*2))/100)))) -> 0.5175 | T13: =IF(ISBLANK(S13),,IF(S13>=0.975,"A+",IF(S13>=0.925,"A",IF(S13>=0.895,"A-",IF(S13>=0.865,"B+",IF(S13>=0.825,"B",IF(S13>=0.795,"B-",IF(S13>=0.765,"C+",IF(S13>=0.725,"C",IF(S13>=0.695,"C-",IF(S13>=0.665,"D+",IF(S13>=0.625,"D",IF(S13>=0.595,"D-",IF(S13<0.6,"F")))))))))))))) -> F | U13: No | V13: =IF(ISBLANK(C13),,IFERROR(IF(VLOOKUP(B13,Standings!$A:$F, 6, 0)=VLOOKUP(C13,Standings!$A:$F, 6, 0), VLOOKUP(B13,Standings!$A:$F, 6, 0), "Non-con"), "FCS")) -> SEC | W13: =IF(ISBLANK(O13),,IF(O13>0,C13,B13)) -> Mississippi State | X13: =IF(ISBLANK(O13),,IF(O13<0,C13,B13)) -> Alabama | Y13: =IF(D13=0,,IF(ISBLANK(Q13),,VLOOKUP(X13,Week8,2,FALSE)/(VLOOKUP(X13,Week8,2,FALSE)+VLOOKUP(W13,Week8,2,FALSE))+0.05)*100) -> 80.892784 | Z13: Alabama | AA13: 41 | AB13: =IF(Z13<>"",(IF(Z13=B13, C13, B13)),"") -> Mississippi State | AC13: 0 | AE13: =IF(ISBLANK(AC13),,AA13-AC13) -> 41 | AG13: =IF(ISBLANK(S13),,If(X13=Z13, 1, 0)) -> 1
A14: 17 | B14: Georgia | C14: Cincinnati | D14: =IFERROR(VLOOKUP(B14,Week16,2,FALSE),0) -> 75.64 | E14: =IF(ISBLANK(B14),,IFERROR(VLOOKUP(B14,CurrentRank!$B$2:$C$132,2,FALSE),0)) -> 79.21 | F14: =IFERROR(VLOOKUP(B14,Week16,3,FALSE),130) -> 10 | G14: =IF(ISBLANK(B14),,IFERROR(VLOOKUP(B14,CurrentRank!$B$2:$D$132,3,FALSE),130)) -> 6 | H14: =IFERROR(VLOOKUP(C14,Week16,2,FALSE),0) -> 82.18 | I14: =IF(ISBLANK(B14),,IFERROR(VLOOKUP(C14,CurrentRank!$B$2:$C$132,2,FALSE),0)) -> 72.9 | J14: =IFERROR(VLOOKUP(C14,Week16,3,FALSE),130) -> 6 | K14: =IF(ISBLANK(C14),,IFERROR(VLOOKUP(C14,CurrentRank!$B$2:$D$132,3,FALSE),130)) -> 9 | L14: =IF(U14= "Yes", 0, IF(ISBLANK(C14),,(D14+H14)*0.015)) -> 0 | M14: =IF(U14= "Yes", 0, IF(ISBLANK(D14),,(E14+I14)*0.015)) -> 0 | N14: =IF(ISBLANK(C14),,(F14+J14)/2) -> 8 | O14: =IF(H14=0,,(D14-(H14+L14))/2) -> -3.27 | P14: =IF(ISBLANK(C14),,(E14-(I14+L14))/2) -> 3.155 | Q14: =IF(ISBLANK(O14),,1-((ABS(O14/2)+N14/2)/100)) -> 0.94365 | R14: =IF(ISBLANK(Q14),,IF(Q14>=0.975,"A+",IF(Q14>=0.925,"A",IF(Q14>=0.895,"A-",IF(Q14>=0.865,"B+",IF(Q14>=0.825,"B",IF(Q14>=0.795,"B-",IF(Q14>=0.765,"C+",IF(Q14>=0.725,"C",IF(Q14>=0.695,"C-",IF(Q14>=0.665,"D+",IF(Q14>=0.625,"D",IF(Q14>=0.595,"D-",IF(Q14<0.6,"F")))))))))))))) -> A | S14: =IF(IF(H14=0,,IF(ISBLANK(AC14),,1-(((AE14/2+N14/2)-(AD14*2))/100)))>1, 1, IF(H14=0,,IF(ISBLANK(AC14),,1-(((AE14/2+N14/2)-(AD14*2))/100)))) -> 0.945 | T14: =IF(ISBLANK(S14),,IF(S14>=0.975,"A+",IF(S14>=0.925,"A",IF(S14>=0.895,"A-",IF(S14>=0.865,"B+",IF(S14>=0.825,"B",IF(S14>=0.795,"B-",IF(S14>=0.765,"C+",IF(S14>=0.725,"C",IF(S14>=0.695,"C-",IF(S14>=0.665,"D+",IF(S14>=0.625,"D",IF(S14>=0.595,"D-",IF(S14<0.6,"F")))))))))))))) -> A | U14: Yes | V14: =IF(ISBLANK(C14),,IFERROR(IF(VLOOKUP(B14,Standings!$A:$F, 6, 0)=VLOOKUP(C14,Standings!$A:$F, 6, 0), VLOOKUP(B14,Standings!$A:$F, 6, 0), "Non-con"), "FCS")) -> Non-con | W14: =IF(ISBLANK(O14),,IF(O14>0,C14,B14)) -> Georgia | X14: =IF(ISBLANK(O14),,IF(O14<0,C14,B14)) -> Cincinnati | Y14: =IF(D14=0,,IF(ISBLANK(Q14),,VLOOKUP(X14,Week16,2,FALSE)/(VLOOKUP(X14,Week16,2,FALSE)+VLOOKUP(W14,Week16,2,FALSE)))*100) -> 52.071981 | Z14: Georgia | AA14: 24 | AB14: =IF(Z14<>"",(IF(Z14=B14, C14, B14)),"") -> Cincinnati | AC14: 21 | AE14: =IF(ISBLANK(AC14),,AA14-AC14) -> 3 | AF14: BOWL | AG14: =IF(ISBLANK(S14),,If(X14=Z14, 1, 0)) -> 0
A15: 12 | B15: Florida | C15: Vanderbilt | D15: =IFERROR(VLOOKUP(B15,Week11,2,FALSE),0) -> 80 | E15: =IF(ISBLANK(B15),,IFERROR(VLOOKUP(B15,CurrentRank!$B$2:$C$132,2,FALSE),0)) -> 68.03 | F15: =IFERROR(VLOOKUP(B15,Week11,3,FALSE),130) -> 7 | G15: =IF(ISBLANK(B15),,IFERROR(VLOOKUP(B15,CurrentRank!$B$2:$D$132,3,FALSE),130)) -> 16 | H15: =IFERROR(VLOOKUP(C15,Week11,2,FALSE),0) -> 26.23 | I15: =IF(ISBLANK(B15),,IFERROR(VLOOKUP(C15,CurrentRank!$B$2:$C$132,2,FALSE),0)) -> 25.47 | J15: =IFERROR(VLOOKUP(C15,Week11,3,FALSE),130) -> 123 | K15: =IF(ISBLANK(C15),,IFERROR(VLOOKUP(C15,CurrentRank!$B$2:$D$132,3,FALSE),130)) -> 125 | L15: =IF(U15= "Yes", 0, IF(ISBLANK(C15),,(D15+H15)*0.015)) -> 1.59345 | M15: =IF(U15= "Yes", 0, IF(ISBLANK(D15),,(E15+I15)*0.015)) -> 1.4025 | N15: =IF(ISBLANK(C15),,(F15+J15)/2) -> 65 | O15: =IF(H15=0,,(D15-(H15+L15))/2) -> 26.088275 | P15: =IF(ISBLANK(C15),,(E15-(I15+L15))/2) -> 20.483275 | Q15: =IF(ISBLANK(O15),,1-((ABS(O15/2)+N15/2)/100)) -> 0.54455862 | R15: =IF(ISBLANK(Q15),,IF(Q15>=0.975,"A+",IF(Q15>=0.925,"A",IF(Q15>=0.895,"A-",IF(Q15>=0.865,"B+",IF(Q15>=0.825,"B",IF(Q15>=0.795,"B-",IF(Q15>=0.765,"C+",IF(Q15>=0.725,"C",IF(Q15>=0.695,"C-",IF(Q15>=0.665,"D+",IF(Q15>=0.625,"D",IF(Q15>=0.595,"D-",IF(Q15<0.6,"F")))))))))))))) -> F | S15: =IF(IF(H15=0,,IF(ISBLANK(AC15),,1-(((AE15/2+N15/2)-(AD15*2))/100)))>1, 1, IF(H15=0,,IF(ISBLANK(AC15),,1-(((AE15/2+N15/2)-(AD15*2))/100)))) -> 0.57 | T15: =IF(ISBLANK(S15),,IF(S15>=0.975,"A+",IF(S15>=0.925,"A",IF(S15>=0.895,"A-",IF(S15>=0.865,"B+",IF(S15>=0.825,"B",IF(S15>=0.795,"B-",IF(S15>=0.765,"C+",IF(S15>=0.725,"C",IF(S15>=0.695,"C-",IF(S15>=0.665,"D+",IF(S15>=0.625,"D",IF(S15>=0.595,"D-",IF(S15<0.6,"F")))))))))))))) -> F | U15: No | V15: =IF(ISBLANK(C15),,IFERROR(IF(VLOOKUP(B15,Standings!$A:$F, 6, 0)=VLOOKUP(C15,Standings!$A:$F, 6, 0), VLOOKUP(B15,Standings!$A:$F, 6, 0), "Non-con"), "FCS")) -> SEC | W15: =IF(ISBLANK(O15),,IF(O15>0,C15,B15)) -> Vanderbilt | X15: =IF(ISBLANK(O15),,IF(O15<0,C15,B15)) -> Florida | Y15: =IF(D15=0,,IF(ISBLANK(Q15),,VLOOKUP(X15,Week11,2,FALSE)/(VLOOKUP(X15,Week11,2,FALSE)+VLOOKUP(W15,Week11,2,FALSE))+0.05)*100) -> 80.308293 | Z15: Florida | AA15: 38 | AB15: =IF(Z15<>"",(IF(Z15=B15, C15, B15)),"") -> Vanderbilt | AC15: 17 | AE15: =IF(ISBLANK(AC15),,AA15-AC15) -> 21 | AG15: =IF(ISBLANK(S15),,If(X15=Z15, 1, 0)) -> 1 | AJ15: Houston
A16: 8 | B16: Tulsa | C16: South Florida | D16: =IFERROR(VLOOKUP(B16,Week7,2,FALSE),0) -> 38.56 | E16: =IF(ISBLANK(B16),,IFERROR(VLOOKUP(B16,CurrentRank!$B$2:$C$132,2,FALSE),0)) -> 37.38 | F16: =IFERROR(VLOOKUP(B16,Week7,3,FALSE),130) -> 41 | G16: =IF(ISBLANK(B16),,IFERROR(VLOOKUP(B16,CurrentRank!$B$2:$D$132,3,FALSE),130)) -> 43 | H16: =IFERROR(VLOOKUP(C16,Week7,2,FALSE),0) -> 12.76 | I16: =IF(ISBLANK(B16),,IFERROR(VLOOKUP(C16,CurrentRank!$B$2:$C$132,2,FALSE),0)) -> 13.91 | J16: =IFERROR(VLOOKUP(C16,Week7,3,FALSE),130) -> 130 | K16: =IF(ISBLANK(C16),,IFERROR(VLOOKUP(C16,CurrentRank!$B$2:$D$132,3,FALSE),130)) -> 129 | L16: =IF(U16= "Yes", 0, IF(ISBLANK(C16),,(D16+H16)*0.015)) -> 0.7698 | M16: =IF(U16= "Yes", 0, IF(ISBLANK(D16),,(E16+I16)*0.015)) -> 0.76935 | N16: =IF(ISBLANK(C16),,(F16+J16)/2) -> 85.5 | O16: =IF(H16=0,,(D16-(H16+L16))/2) -> 12.5151 | P16: =IF(ISBLANK(C16),,(E16-(I16+L16))/2) -> 11.3501 | Q16: =IF(ISBLANK(O16),,1-((ABS(O16/2)+N16/2)/100)) -> 0.5099245 | R16: =IF(ISBLANK(Q16),,IF(Q16>=0.975,"A+",IF(Q16>=0.925,"A",IF(Q16>=0.895,"A-",IF(Q16>=0.865,"B+",IF(Q16>=0.825,"B",IF(Q16>=0.795,"B-",IF(Q16>=0.765,"C+",IF(Q16>=0.725,"C",IF(Q16>=0.695,"C-",IF(Q16>=0.665,"D+",IF(Q16>=0.625,"D",IF(Q16>=0.595,"D-",IF(Q16<0.6,"F")))))))))))))) -> F | S16: =IF(IF(H16=0,,IF(ISBLANK(AC16),,1-(((AE16/2+N16/2)-(AD16*2))/100)))>1, 1, IF(H16=0,,IF(ISBLANK(AC16),,1-(((AE16/2+N16/2)-(AD16*2))/100)))) -> 0.4275 | T16: =IF(ISBLANK(S16),,IF(S16>=0.975,"A+",IF(S16>=0.925,"A",IF(S16>=0.895,"A-",IF(S16>=0.865,"B+",IF(S16>=0.825,"B",IF(S16>=0.795,"B-",IF(S16>=0.765,"C+",IF(S16>=0.725,"C",IF(S16>=0.695,"C-",IF(S16>=0.665,"D+",IF(S16>=0.625,"D",IF(S16>=0.595,"D-",IF(S16<0.6,"F")))))))))))))) -> F | U16: No | V16: =IF(ISBLANK(C16),,IFERROR(IF(VLOOKUP(B16,Standings!$A:$F, 6, 0)=VLOOKUP(C16,Standings!$A:$F, 6, 0), VLOOKUP(B16,Standings!$A:$F, 6, 0), "Non-con"), "FCS")) -> AAC | W16: =IF(ISBLANK(O16),,IF(O16>0,C16,B16)) -> South Florida | X16: =IF(ISBLANK(O16),,IF(O16<0,C16,B16)) -> Tulsa | Y16: =IF(D16=0,,IF(ISBLANK(Q16),,VLOOKUP(X16,Week7,2,FALSE)/(VLOOKUP(X16,Week7,2,FALSE)+VLOOKUP(W16,Week7,2,FALSE))+0.05)*100) -> 80.136399 | Z16: Tulsa | AA16: 42 | AB16: =IF(Z16<>"",(IF(Z16=B16, C16, B16)),"") -> South Florida | AC16: 13 | AE16: =IF(ISBLANK(AC16),,AA16-AC16) -> 29 | AG16: =IF(ISBLANK(S16),,If(X16=Z16, 1, 0)) -> 1
A17: 17 | B17: Liberty | C17: Coastal Carolina | D17: =IFERROR(VLOOKUP(B17,Week16,2,FALSE),0) -> 59.47 | E17: =IF(ISBLANK(B17),,IFERROR(VLOOKUP(B17,CurrentRank!$B$2:$C$132,2,FALSE),0)) -> 65.58 | F17: =IFERROR(VLOOKUP(B17,Week16,3,FALSE),130) -> 21 | G17: =IF(ISBLANK(B17),,IFERROR(VLOOKUP(B17,CurrentRank!$B$2:$D$132,3,FALSE),130)) -> 17 | H17: =IFERROR(VLOOKUP(C17,Week16,2,FALSE),0) -> 83.31 | I17: =IF(ISBLANK(B17),,IFERROR(VLOOKUP(C17,CurrentRank!$B$2:$C$132,2,FALSE),0)) -> 69.98 | J17: =IFERROR(VLOOKUP(C17,Week16,3,FALSE),130) -> 5 | K17: =IF(ISBLANK(C17),,IFERROR(VLOOKUP(C17,CurrentRank!$B$2:$D$132,3,FALSE),130)) -> 13 | L17: =IF(U17= "Yes", 0, IF(ISBLANK(C17),,(D17+H17)*0.015)) -> 0 | M17: =IF(U17= "Yes", 0, IF(ISBLANK(D17),,(E17+I17)*0.015)) -> 0 | N17: =IF(ISBLANK(C17),,(F17+J17)/2) -> 13 | O17: =IF(H17=0,,(D17-(H17+L17))/2) -> -11.92 | P17: =IF(ISBLANK(C17),,(E17-(I17+L17))/2) -> -2.2 | Q17: =IF(ISBLANK(O17),,1-((ABS(O17/2)+N17/2)/100)) -> 0.8754 | R17: =IF(ISBLANK(Q17),,IF(Q17>=0.975,"A+",IF(Q17>=0.925,"A",IF(Q17>=0.895,"A-",IF(Q17>=0.865,"B+",IF(Q17>=0.825,"B",IF(Q17>=0.795,"B-",IF(Q17>=0.765,"C+",IF(Q17>=0.725,"C",IF(Q17>=0.695,"C-",IF(Q17>=0.665,"D+",IF(Q17>=0.625,"D",IF(Q17>=0.595,"D-",IF(Q17<0.6,"F")))))))))))))) -> B+ | S17: =IF(IF(H17=0,,IF(ISBLANK(AC17),,1-(((AE17/2+N17/2)-(AD17*2))/100)))>1, 1, IF(H17=0,,IF(ISBLANK(AC17),,1-(((AE17/2+N17/2)-(AD17*2))/100)))) -> 0.94 | T17: =IF(ISBLANK(S17),,IF(S17>=0.975,"A+",IF(S17>=0.925,"A",IF(S17>=0.895,"A-",IF(S17>=0.865,"B+",IF(S17>=0.825,"B",IF(S17>=0.795,"B-",IF(S17>=0.765,"C+",IF(S17>=0.725,"C",IF(S17>=0.695,"C-",IF(S17>=0.665,"D+",IF(S17>=0.625,"D",IF(S17>=0.595,"D-",IF(S17<0.6,"F")))))))))))))) -> A | U17: Yes | V17: =IF(ISBLANK(C17),,IFERROR(IF(VLOOKUP(B17,Standings!$A:$F, 6, 0)=VLOOKUP(C17,Standings!$A:$F, 6, 0), VLOOKUP(B17,Standings!$A:$F, 6, 0), "Non-con"), "FCS")) -> Non-con | W17: =IF(ISBLANK(O17),,IF(O17>0,C17,B17)) -> Liberty | X17: =IF(ISBLANK(O17),,IF(O17<0,C17,B17)) -> Coastal Carolina | Y17: =IF(D17=0,,IF(ISBLANK(Q17),,VLOOKUP(X17,Week16,2,FALSE)/(VLOOKUP(X17,Week16,2,FALSE)+VLOOKUP(W17,Week16,2,FALSE)))*100) -> 58.348508 | Z17: Liberty | AA17: 37 | AB17: =IF(Z17<>"",(IF(Z17=B17, C17, B17)),"") -> Coastal Carolina | AC17: 34 | AD17: 1 | AE17: =IF(ISBLANK(AC17),,AA17-AC17) -> 3 | AF17: BOWL | AG17: =IF(ISBLANK(S17),,If(X17=Z17, 1, 0)) -> 0
A18: 12 | B18: Clemson | C18: Florida State | D18: =IFERROR(VLOOKUP(B18,CurrentRank!$B$2:$C$132,2,FALSE),0) -> 84.24 | E18: =IF(ISBLANK(B18),,IFERROR(VLOOKUP(B18,CurrentRank!$B$2:$C$132,2,FALSE),0)) -> 84.24 | F18: =IFERROR(VLOOKUP(B18,CurrentRank!$B$2:$D$132,3,FALSE),130) -> 4 | G18: =IF(ISBLANK(B18),,IFERROR(VLOOKUP(B18,CurrentRank!$B$2:$D$132,3,FALSE),130)) -> 4 | H18: =IFERROR(VLOOKUP(C18,CurrentRank!$B$2:$C$132,2,FALSE),0) -> 32.08 | I18: =IF(ISBLANK(B18),,IFERROR(VLOOKUP(C18,CurrentRank!$B$2:$C$132,2,FALSE),0)) -> 32.08 | J18: =IFERROR(VLOOKUP(C18,Week11,3,FALSE),130) -> 118 | K18: =IFERROR(VLOOKUP(C18,CurrentRank!$B$2:$D$132,3,FALSE),130) -> 93 | L18: =IF(ISBLANK(C18),,(D18+H18)*0.015) -> 1.7448 | M18: =IF(ISBLANK(D18),,(E18+I18)*0.015) -> 1.7448 | N18: =F18+K18 -> 97 | O18: =IF(H18=0,,(D18-(H18+L18))/2) -> 25.2076 | P18: =(D18-(H18+L18))/2 -> 25.2076 | Q18: =IF(ISBLANK(O18),,1-((ABS(O18/2)+N18/2)/100)) -> 0.388962 | R18: =IF(ISBLANK(Q18),,IF(Q18>=0.975,"A+",IF(Q18>=0.925,"A",IF(Q18>=0.895,"A-",IF(Q18>=0.865,"B+",IF(Q18>=0.825,"B",IF(Q18>=0.795,"B-",IF(Q18>=0.765,"C+",IF(Q18>=0.725,"C",IF(Q18>=0.695,"C-",IF(Q18>=0.665,"D+",IF(Q18>=0.625,"D",IF(Q18>=0.595,"D-",IF(Q18<0.6,"F")))))))))))))) -> F | S18: =IF(IF(H18=0,,IF(ISBLANK(AC18),,1-(((AE18/2+N18/2)-(AD18*2))/100)))>1, 1, IF(H18=0,,IF(ISBLANK(AC18),,1-(((AE18/2+N18/2)-(AD18*2))/100)))) | T18: =IF(ISBLANK(S18),,IF(S18>=0.975,"A+",IF(S18>=0.925,"A",IF(S18>=0.895,"A-",IF(S18>=0.865,"B+",IF(S18>=0.825,"B",IF(S18>=0.795,"B-",IF(S18>=0.765,"C+",IF(S18>=0.725,"C",IF(S18>=0.695,"C-",IF(S18>=0.665,"D+",IF(S18>=0.625,"D",IF(S18>=0.595,"D-",IF(S18<0.6,"F")))))))))))))) | U18: No | V18: =IFERROR(IF(VLOOKUP(B18,Standings!$A:$F, 6, 0)=VLOOKUP(C18,Standings!$A:$F, 6, 0), VLOOKUP(B18,Standings!$A:$F, 6, 0), "Non-con"), "FCS") -> ACC | W18: =IF(ISBLANK(O18),,IF(O18>0,C18,B18)) -> Florida State | X18: =IF(ISBLANK(O18),,IF(O18<0,C18,B18)) -> Clemson | Y18: =IF(D18=0,,IF(ISBLANK(Q18),,VLOOKUP(X18,Week11,2,FALSE)/(VLOOKUP(X18,Week11,2,FALSE)+VLOOKUP(W18,Week11,2,FALSE))+0.05)*100) -> 80.101015 | AE18: =IF(ISBLANK(AC18),,AA18-AC18) | AF18: CAN | AG18: =IF(ISBLANK(S18),,If(X18=Z18, 1, 0))
